ERROR:telegram.ext.Updater:Error while getting Updates: Conflict: terminated by other getUpdates request; make sure that only one bot instance is running
ERROR:telegram.ext.Application:No error handlers are registered, logging exception.
Traceback (most recent call last):
  File "C:\Users\Kamil\AppData\Roaming\Python\Python313\site-packages\telegram\ext\_updater.py", line 742, in _network_loop_retry
    if not await do_action():
           ^^^^^^^^^^^^^^^^^
  File "C:\Users\Kamil\AppData\Roaming\Python\Python313\site-packages\telegram\ext\_updater.py", line 736, in do_action
    return action_cb_task.result()
           ~~~~~~~~~~~~~~~~~~~~~^^
  File "C:\Users\Kamil\AppData\Roaming\Python\Python313\site-packages\telegram\ext\_updater.py", line 387, in polling_action_cb
    raise exc
  File "C:\Users\Kamil\AppData\Roaming\Python\Python313\site-packages\telegram\ext\_updater.py", line 376, in polling_action_cb
    updates = await self.bot.get_updates(
              ^^^^^^^^^^^^^^^^^^^^^^^^^^^
    ...<7 lines>...
    )
    ^
  File "C:\Users\Kamil\AppData\Roaming\Python\Python313\site-packages\telegram\ext\_extbot.py", line 618, in get_updates
    updates = await super().get_updates(
              ^^^^^^^^^^^^^^^^^^^^^^^^^^
    ...<9 lines>...
    )
    ^
  File "C:\Users\Kamil\AppData\Roaming\Python\Python313\site-packages\telegram\_bot.py", line 541, in decorator
    result = await func(self, *args, **kwargs)
             ^^^^^^^^^^^^^^^^^^^^^^^^^^^^^^^^^
  File "C:\Users\Kamil\AppData\Roaming\Python\Python313\site-packages\telegram\_bot.py", line 4177, in get_updates
    await self._post(
    ^^^^^^^^^^^^^^^^^
    ...<7 lines>...
    ),
    ^
  File "C:\Users\Kamil\AppData\Roaming\Python\Python313\site-packages\telegram\_bot.py", line 629, in _post
    return await self._do_post(
           ^^^^^^^^^^^^^^^^^^^^
    ...<6 lines>...
    )
    ^
  File "C:\Users\Kamil\AppData\Roaming\Python\Python313\site-packages\telegram\ext\_extbot.py", line 347, in _do_post
    return await super()._do_post(
           ^^^^^^^^^^^^^^^^^^^^^^^
    ...<6 lines>...
    )
    ^
  File "C:\Users\Kamil\AppData\Roaming\Python\Python313\site-packages\telegram\_bot.py", line 657, in _do_post
    return await request.post(
           ^^^^^^^^^^^^^^^^^^^
    ...<6 lines>...
    )
    ^
  File "C:\Users\Kamil\AppData\Roaming\Python\Python313\site-packages\telegram\request\_baserequest.py", line 200, in post
    result = await self._request_wrapper(
             ^^^^^^^^^^^^^^^^^^^^^^^^^^^^
    ...<7 lines>...
    )
    ^
  File "C:\Users\Kamil\AppData\Roaming\Python\Python313\site-packages\telegram\request\_baserequest.py", line 381, in _request_wrapper
    raise Conflict(message)
telegram.error.Conflict: Conflict: terminated by other getUpdates request; make sure that only one bot instance is running
ERROR:root:[GPT] Ошибка с моделью openai/gpt-4o: Код: 402 | {"error":{"message":"This request requires more credits, or fewer max_tokens. You requested up to 1000 tokens, but can only afford 953. To increase, visit https://openrouter.ai/settings/credits and upgrade to a paid account","code":402,"metadata":{"provider_name":null}},"user_id":"user_2yEbVfDzUm3gZaKSeuRlPbqvTju"}
ERROR:root:[GPT] Ошибка с моделью openai/gpt-3.5-turbo: Код: 404 | {"error":{"message":"No endpoints found for openai/gpt-3.5-turbo.","code":404},"user_id":"user_2yEbVfDzUm3gZaKSeuRlPbqvTju"}
ERROR:root:[GPT] Ошибка с моделью deepseek-ai/deepseek-coder: Код: 400 | {"error":{"message":"deepseek-ai/deepseek-coder is not a valid model ID","code":400},"user_id":"user_2yEbVfDzUm3gZaKSeuRlPbqvTju"}
ERROR:root:[GPT] Ошибка с моделью google/gemini-pro: Код: 400 | {"error":{"message":"google/gemini-pro is not a valid model ID","code":400},"user_id":"user_2yEbVfDzUm3gZaKSeuRlPbqvTju"}
ERROR:root:[GPT] Ошибка с моделью openai/gpt-4o: Код: 402 | {"error":{"message":"This request requires more credits, or fewer max_tokens. You requested up to 1000 tokens, but can only afford 952. To increase, visit https://openrouter.ai/settings/credits and upgrade to a paid account","code":402,"metadata":{"provider_name":null}},"user_id":"user_2yEbVfDzUm3gZaKSeuRlPbqvTju"}
ERROR:root:[GPT] Ошибка с моделью openai/gpt-3.5-turbo: Код: 404 | {"error":{"message":"No endpoints found for openai/gpt-3.5-turbo.","code":404},"user_id":"user_2yEbVfDzUm3gZaKSeuRlPbqvTju"}
ERROR:root:[GPT] Ошибка с моделью deepseek-ai/deepseek-coder: Код: 400 | {"error":{"message":"deepseek-ai/deepseek-coder is not a valid model ID","code":400},"user_id":"user_2yEbVfDzUm3gZaKSeuRlPbqvTju"}
ERROR:root:[GPT] Ошибка с моделью google/gemini-pro: Код: 400 | {"error":{"message":"google/gemini-pro is not a valid model ID","code":400},"user_id":"user_2yEbVfDzUm3gZaKSeuRlPbqvTju"}
