2025-07-01 15:09:22,543 ERROR No error handlers are registered, logging exception.
Traceback (most recent call last):
  File "/home/KamilSultan/.local/lib/python3.13/site-packages/telegram/ext/_application.py", line 1124, in process_update
    await coroutine
  File "/home/KamilSultan/.local/lib/python3.13/site-packages/telegram/ext/_conversationhandler.py", line 825, in handle_update
    new_state: object = await handler.handle_update(
                        ^^^^^^^^^^^^^^^^^^^^^^^^^^^^
        update, application, handler_check_result, context
        ^^^^^^^^^^^^^^^^^^^^^^^^^^^^^^^^^^^^^^^^^^^^^^^^^^
    )
    ^
  File "/home/KamilSultan/.local/lib/python3.13/site-packages/telegram/ext/_handler.py", line 141, in handle_update
    return await self.callback(update, context)
           ^^^^^^^^^^^^^^^^^^^^^^^^^^^^^^^^^^^^
  File "/home/KamilSultan/psych_bot/bot.py", line 41, in button_handler
    if q.data == "reset": return await start(update, ctx)
                                 ^^^^^^^^^^^^^^^^^^^^^^^^
  File "/home/KamilSultan/psych_bot/bot.py", line 35, in start
    await update.message.reply_text("Введите код пары:", reply_markup=make_keyboard(ASK_CODE))
          ^^^^^^^^^^^^^^^^^^^^^^^^^
AttributeError: 'NoneType' object has no attribute 'reply_text'
ERROR:root:Ошибка проверки использования кода: list index out of range
ERROR:root:Ошибка проверки использования кода: list index out of range
ERROR:root:Ошибка проверки использования кода: list index out of range
ERROR:root:Ошибка проверки использования кода: list index out of range
ERROR:root:Ошибка проверки использования кода: list index out of range
ERROR:root:[GPT] Ошибка с моделью openai/gpt-4o: 

You tried to access openai.ChatCompletion, but this is no longer supported in openai>=1.0.0 - see the README at https://github.com/openai/openai-python for the API.

You can run `openai migrate` to automatically upgrade your codebase to use the 1.0.0 interface. 

Alternatively, you can pin your installation to the old version, e.g. `pip install openai==0.28`

A detailed migration guide is available here: https://github.com/openai/openai-python/discussions/742

ERROR:root:[GPT] Ошибка с моделью openai/gpt-3.5-turbo: 

You tried to access openai.ChatCompletion, but this is no longer supported in openai>=1.0.0 - see the README at https://github.com/openai/openai-python for the API.

You can run `openai migrate` to automatically upgrade your codebase to use the 1.0.0 interface. 

Alternatively, you can pin your installation to the old version, e.g. `pip install openai==0.28`

A detailed migration guide is available here: https://github.com/openai/openai-python/discussions/742

ERROR:root:[GPT] Ошибка с моделью deepseek-ai/deepseek-coder: 

You tried to access openai.ChatCompletion, but this is no longer supported in openai>=1.0.0 - see the README at https://github.com/openai/openai-python for the API.

You can run `openai migrate` to automatically upgrade your codebase to use the 1.0.0 interface. 

Alternatively, you can pin your installation to the old version, e.g. `pip install openai==0.28`

A detailed migration guide is available here: https://github.com/openai/openai-python/discussions/742

ERROR:root:[GPT] Ошибка с моделью google/gemini-pro: 

You tried to access openai.ChatCompletion, but this is no longer supported in openai>=1.0.0 - see the README at https://github.com/openai/openai-python for the API.

You can run `openai migrate` to automatically upgrade your codebase to use the 1.0.0 interface. 

Alternatively, you can pin your installation to the old version, e.g. `pip install openai==0.28`

A detailed migration guide is available here: https://github.com/openai/openai-python/discussions/742

ERROR:root:[GPT] Ошибка с моделью mistralai/mistral-7b-instruct: 

You tried to access openai.ChatCompletion, but this is no longer supported in openai>=1.0.0 - see the README at https://github.com/openai/openai-python for the API.

You can run `openai migrate` to automatically upgrade your codebase to use the 1.0.0 interface. 

Alternatively, you can pin your installation to the old version, e.g. `pip install openai==0.28`

A detailed migration guide is available here: https://github.com/openai/openai-python/discussions/742

ERROR:root:[GPT] Ошибка с моделью openai/gpt-4o: 

You tried to access openai.ChatCompletion, but this is no longer supported in openai>=1.0.0 - see the README at https://github.com/openai/openai-python for the API.

You can run `openai migrate` to automatically upgrade your codebase to use the 1.0.0 interface. 

Alternatively, you can pin your installation to the old version, e.g. `pip install openai==0.28`

A detailed migration guide is available here: https://github.com/openai/openai-python/discussions/742

ERROR:root:[GPT] Ошибка с моделью openai/gpt-3.5-turbo: 

You tried to access openai.ChatCompletion, but this is no longer supported in openai>=1.0.0 - see the README at https://github.com/openai/openai-python for the API.

You can run `openai migrate` to automatically upgrade your codebase to use the 1.0.0 interface. 

Alternatively, you can pin your installation to the old version, e.g. `pip install openai==0.28`

A detailed migration guide is available here: https://github.com/openai/openai-python/discussions/742

ERROR:root:[GPT] Ошибка с моделью deepseek-ai/deepseek-coder: 

You tried to access openai.ChatCompletion, but this is no longer supported in openai>=1.0.0 - see the README at https://github.com/openai/openai-python for the API.

You can run `openai migrate` to automatically upgrade your codebase to use the 1.0.0 interface. 

Alternatively, you can pin your installation to the old version, e.g. `pip install openai==0.28`

A detailed migration guide is available here: https://github.com/openai/openai-python/discussions/742

ERROR:root:[GPT] Ошибка с моделью google/gemini-pro: 

You tried to access openai.ChatCompletion, but this is no longer supported in openai>=1.0.0 - see the README at https://github.com/openai/openai-python for the API.

You can run `openai migrate` to automatically upgrade your codebase to use the 1.0.0 interface. 

Alternatively, you can pin your installation to the old version, e.g. `pip install openai==0.28`

A detailed migration guide is available here: https://github.com/openai/openai-python/discussions/742

ERROR:root:[GPT] Ошибка с моделью mistralai/mistral-7b-instruct: 

You tried to access openai.ChatCompletion, but this is no longer supported in openai>=1.0.0 - see the README at https://github.com/openai/openai-python for the API.

You can run `openai migrate` to automatically upgrade your codebase to use the 1.0.0 interface. 

Alternatively, you can pin your installation to the old version, e.g. `pip install openai==0.28`

A detailed migration guide is available here: https://github.com/openai/openai-python/discussions/742

ERROR:telegram.ext.Updater:Error while getting Updates: httpx.ProxyError: 503 Service Unavailable
ERROR:telegram.ext.Application:No error handlers are registered, logging exception.
Traceback (most recent call last):
  File "/home/KamilSultan/.local/lib/python3.13/site-packages/httpx/_transports/default.py", line 60, in map_httpcore_exceptions
    yield
  File "/home/KamilSultan/.local/lib/python3.13/site-packages/httpx/_transports/default.py", line 353, in handle_async_request
    resp = await self._pool.handle_async_request(req)
           ^^^^^^^^^^^^^^^^^^^^^^^^^^^^^^^^^^^^^^^^^^
  File "/home/KamilSultan/.local/lib/python3.13/site-packages/httpcore/_async/connection_pool.py", line 262, in handle_async_request
    raise exc
  File "/home/KamilSultan/.local/lib/python3.13/site-packages/httpcore/_async/connection_pool.py", line 245, in handle_async_request
    response = await connection.handle_async_request(request)
               ^^^^^^^^^^^^^^^^^^^^^^^^^^^^^^^^^^^^^^^^^^^^^^
  File "/home/KamilSultan/.local/lib/python3.13/site-packages/httpcore/_async/http_proxy.py", line 280, in handle_async_request
    raise ProxyError(msg)
httpcore.ProxyError: 503 Service Unavailable

The above exception was the direct cause of the following exception:

Traceback (most recent call last):
  File "/home/KamilSultan/.local/lib/python3.13/site-packages/telegram/request/_httpxrequest.py", line 216, in do_request
    res = await self._client.request(
          ^^^^^^^^^^^^^^^^^^^^^^^^^^^
    ...<6 lines>...
    )
    ^
  File "/home/KamilSultan/.local/lib/python3.13/site-packages/httpx/_client.py", line 1530, in request
    return await self.send(request, auth=auth, follow_redirects=follow_redirects)
           ^^^^^^^^^^^^^^^^^^^^^^^^^^^^^^^^^^^^^^^^^^^^^^^^^^^^^^^^^^^^^^^^^^^^^^
  File "/home/KamilSultan/.local/lib/python3.13/site-packages/httpx/_client.py", line 1617, in send
    response = await self._send_handling_auth(
               ^^^^^^^^^^^^^^^^^^^^^^^^^^^^^^^
    ...<4 lines>...
    )
    ^
  File "/home/KamilSultan/.local/lib/python3.13/site-packages/httpx/_client.py", line 1645, in _send_handling_auth
    response = await self._send_handling_redirects(
               ^^^^^^^^^^^^^^^^^^^^^^^^^^^^^^^^^^^^
    ...<3 lines>...
    )
    ^
  File "/home/KamilSultan/.local/lib/python3.13/site-packages/httpx/_client.py", line 1682, in _send_handling_redirects
    response = await self._send_single_request(request)
               ^^^^^^^^^^^^^^^^^^^^^^^^^^^^^^^^^^^^^^^^
  File "/home/KamilSultan/.local/lib/python3.13/site-packages/httpx/_client.py", line 1719, in _send_single_request
    response = await transport.handle_async_request(request)
               ^^^^^^^^^^^^^^^^^^^^^^^^^^^^^^^^^^^^^^^^^^^^^
  File "/home/KamilSultan/.local/lib/python3.13/site-packages/httpx/_transports/default.py", line 352, in handle_async_request
    with map_httpcore_exceptions():
         ~~~~~~~~~~~~~~~~~~~~~~~^^
  File "/usr/local/lib/python3.13/contextlib.py", line 162, in __exit__
    self.gen.throw(value)
    ~~~~~~~~~~~~~~^^^^^^^
  File "/home/KamilSultan/.local/lib/python3.13/site-packages/httpx/_transports/default.py", line 77, in map_httpcore_exceptions
    raise mapped_exc(message) from exc
httpx.ProxyError: 503 Service Unavailable

The above exception was the direct cause of the following exception:

Traceback (most recent call last):
  File "/home/KamilSultan/.local/lib/python3.13/site-packages/telegram/ext/_updater.py", line 607, in _network_loop_retry
    if not await action_cb():
           ^^^^^^^^^^^^^^^^^
  File "/home/KamilSultan/.local/lib/python3.13/site-packages/telegram/ext/_updater.py", line 335, in polling_action_cb
    raise exc
  File "/home/KamilSultan/.local/lib/python3.13/site-packages/telegram/ext/_updater.py", line 320, in polling_action_cb
    updates = await self.bot.get_updates(
              ^^^^^^^^^^^^^^^^^^^^^^^^^^^
    ...<7 lines>...
    )
    ^
  File "/home/KamilSultan/.local/lib/python3.13/site-packages/telegram/ext/_extbot.py", line 543, in get_updates
    updates = await super().get_updates(
              ^^^^^^^^^^^^^^^^^^^^^^^^^^
    ...<9 lines>...
    )
    ^
  File "/home/KamilSultan/.local/lib/python3.13/site-packages/telegram/_bot.py", line 381, in decorator
    result = await func(self, *args, **kwargs)  # skipcq: PYL-E1102
             ^^^^^^^^^^^^^^^^^^^^^^^^^^^^^^^^^
  File "/home/KamilSultan/.local/lib/python3.13/site-packages/telegram/_bot.py", line 3661, in get_updates
    await self._post(
    ^^^^^^^^^^^^^^^^^
    ...<7 lines>...
    ),
    ^
  File "/home/KamilSultan/.local/lib/python3.13/site-packages/telegram/_bot.py", line 469, in _post
    return await self._do_post(
           ^^^^^^^^^^^^^^^^^^^^
    ...<6 lines>...
    )
    ^
  File "/home/KamilSultan/.local/lib/python3.13/site-packages/telegram/ext/_extbot.py", line 325, in _do_post
    return await super()._do_post(
           ^^^^^^^^^^^^^^^^^^^^^^^
    ...<6 lines>...
    )
    ^
  File "/home/KamilSultan/.local/lib/python3.13/site-packages/telegram/_bot.py", line 497, in _do_post
    return await request.post(
           ^^^^^^^^^^^^^^^^^^^
    ...<6 lines>...
    )
    ^
  File "/home/KamilSultan/.local/lib/python3.13/site-packages/telegram/request/_baserequest.py", line 168, in post
    result = await self._request_wrapper(
             ^^^^^^^^^^^^^^^^^^^^^^^^^^^^
    ...<7 lines>...
    )
    ^
  File "/home/KamilSultan/.local/lib/python3.13/site-packages/telegram/request/_baserequest.py", line 291, in _request_wrapper
    raise exc
  File "/home/KamilSultan/.local/lib/python3.13/site-packages/telegram/request/_baserequest.py", line 277, in _request_wrapper
    code, payload = await self.do_request(
                    ^^^^^^^^^^^^^^^^^^^^^^
    ...<7 lines>...
    )
    ^
  File "/home/KamilSultan/.local/lib/python3.13/site-packages/telegram/request/_httpxrequest.py", line 240, in do_request
    raise NetworkError(f"httpx.{err.__class__.__name__}: {err}") from err
telegram.error.NetworkError: httpx.ProxyError: 503 Service Unavailable
ERROR:root:[GPT] Ошибка с моделью openai/gpt-4o: 

You tried to access openai.ChatCompletion, but this is no longer supported in openai>=1.0.0 - see the README at https://github.com/openai/openai-python for the API.

You can run `openai migrate` to automatically upgrade your codebase to use the 1.0.0 interface. 

Alternatively, you can pin your installation to the old version, e.g. `pip install openai==0.28`

A detailed migration guide is available here: https://github.com/openai/openai-python/discussions/742

ERROR:root:[GPT] Ошибка с моделью openai/gpt-3.5-turbo: 

You tried to access openai.ChatCompletion, but this is no longer supported in openai>=1.0.0 - see the README at https://github.com/openai/openai-python for the API.

You can run `openai migrate` to automatically upgrade your codebase to use the 1.0.0 interface. 

Alternatively, you can pin your installation to the old version, e.g. `pip install openai==0.28`

A detailed migration guide is available here: https://github.com/openai/openai-python/discussions/742

ERROR:root:[GPT] Ошибка с моделью deepseek-ai/deepseek-coder: 

You tried to access openai.ChatCompletion, but this is no longer supported in openai>=1.0.0 - see the README at https://github.com/openai/openai-python for the API.

You can run `openai migrate` to automatically upgrade your codebase to use the 1.0.0 interface. 

Alternatively, you can pin your installation to the old version, e.g. `pip install openai==0.28`

A detailed migration guide is available here: https://github.com/openai/openai-python/discussions/742

ERROR:root:[GPT] Ошибка с моделью google/gemini-pro: 

You tried to access openai.ChatCompletion, but this is no longer supported in openai>=1.0.0 - see the README at https://github.com/openai/openai-python for the API.

You can run `openai migrate` to automatically upgrade your codebase to use the 1.0.0 interface. 

Alternatively, you can pin your installation to the old version, e.g. `pip install openai==0.28`

A detailed migration guide is available here: https://github.com/openai/openai-python/discussions/742

ERROR:root:[GPT] Ошибка с моделью mistralai/mistral-7b-instruct: 

You tried to access openai.ChatCompletion, but this is no longer supported in openai>=1.0.0 - see the README at https://github.com/openai/openai-python for the API.

You can run `openai migrate` to automatically upgrade your codebase to use the 1.0.0 interface. 

Alternatively, you can pin your installation to the old version, e.g. `pip install openai==0.28`

A detailed migration guide is available here: https://github.com/openai/openai-python/discussions/742

ERROR:root:[GPT] Ошибка с моделью openai/gpt-4o: name 'openai' is not defined
ERROR:root:[GPT] Ошибка с моделью openai/gpt-3.5-turbo: name 'openai' is not defined
ERROR:root:[GPT] Ошибка с моделью deepseek-ai/deepseek-coder: name 'openai' is not defined
ERROR:root:[GPT] Ошибка с моделью google/gemini-pro: name 'openai' is not defined
ERROR:root:[GPT] Ошибка с моделью mistralai/mistral-7b-instruct: name 'openai' is not defined
ERROR:telegram.ext.Application:No error handlers are registered, logging exception.
Traceback (most recent call last):
  File "/home/KamilSultan/.local/lib/python3.13/site-packages/telegram/ext/_application.py", line 1124, in process_update
    await coroutine
  File "/home/KamilSultan/.local/lib/python3.13/site-packages/telegram/ext/_conversationhandler.py", line 825, in handle_update
    new_state: object = await handler.handle_update(
                        ^^^^^^^^^^^^^^^^^^^^^^^^^^^^
        update, application, handler_check_result, context
        ^^^^^^^^^^^^^^^^^^^^^^^^^^^^^^^^^^^^^^^^^^^^^^^^^^
    )
    ^
  File "/home/KamilSultan/.local/lib/python3.13/site-packages/telegram/ext/_handler.py", line 141, in handle_update
    return await self.callback(update, context)
           ^^^^^^^^^^^^^^^^^^^^^^^^^^^^^^^^^^^^
  File "/home/KamilSultan/psych_bot/bot.py", line 24, in get_code
    row = find_row_by_code(code)
          ^^^^^^^^^^^^^^^^
NameError: name 'find_row_by_code' is not defined
ERROR:root:[GPT] Ошибка с моделью openai/gpt-4o: Error code: 401 - {'error': {'message': 'Incorrect API key provided: sk-or-v1*************************************************************6e1d. You can find your API key at https://platform.openai.com/account/api-keys.', 'type': 'invalid_request_error', 'param': None, 'code': 'invalid_api_key'}}
ERROR:root:[GPT] Ошибка с моделью openai/gpt-3.5-turbo: Error code: 401 - {'error': {'message': 'Incorrect API key provided: sk-or-v1*************************************************************6e1d. You can find your API key at https://platform.openai.com/account/api-keys.', 'type': 'invalid_request_error', 'param': None, 'code': 'invalid_api_key'}}
ERROR:root:[GPT] Ошибка с моделью deepseek-ai/deepseek-coder: Error code: 401 - {'error': {'message': 'Incorrect API key provided: sk-or-v1*************************************************************6e1d. You can find your API key at https://platform.openai.com/account/api-keys.', 'type': 'invalid_request_error', 'param': None, 'code': 'invalid_api_key'}}
ERROR:root:[GPT] Ошибка с моделью google/gemini-pro: Error code: 401 - {'error': {'message': 'Incorrect API key provided: sk-or-v1*************************************************************6e1d. You can find your API key at https://platform.openai.com/account/api-keys.', 'type': 'invalid_request_error', 'param': None, 'code': 'invalid_api_key'}}
ERROR:root:[GPT] Ошибка с моделью mistralai/mistral-7b-instruct: Error code: 401 - {'error': {'message': 'Incorrect API key provided: sk-or-v1*************************************************************6e1d. You can find your API key at https://platform.openai.com/account/api-keys.', 'type': 'invalid_request_error', 'param': None, 'code': 'invalid_api_key'}}
ERROR:root:[GoogleSheets] Ошибка записи сообщения: {'code': 403, 'message': 'The caller does not have permission', 'status': 'PERMISSION_DENIED'}
ERROR:telegram.ext.Application:No error handlers are registered, logging exception.
Traceback (most recent call last):
  File "/home/KamilSultan/.local/lib/python3.13/site-packages/telegram/ext/_application.py", line 1124, in process_update
    await coroutine
  File "/home/KamilSultan/.local/lib/python3.13/site-packages/telegram/ext/_conversationhandler.py", line 825, in handle_update
    new_state: object = await handler.handle_update(
                        ^^^^^^^^^^^^^^^^^^^^^^^^^^^^
        update, application, handler_check_result, context
        ^^^^^^^^^^^^^^^^^^^^^^^^^^^^^^^^^^^^^^^^^^^^^^^^^^
    )
    ^
  File "/home/KamilSultan/.local/lib/python3.13/site-packages/telegram/ext/_handler.py", line 141, in handle_update
    return await self.callback(update, context)
           ^^^^^^^^^^^^^^^^^^^^^^^^^^^^^^^^^^^^
  File "/home/KamilSultan/psych_bot/bot.py", line 56, in get_message1
    write_message(row, user_id, message, is_first=True)
    ~~~~~~~~~~~~~^^^^^^^^^^^^^^^^^^^^^^^^^^^^^^^^^^^^^^
  File "/home/KamilSultan/psych_bot/sheets.py", line 48, in write_message
    sheet.update_cell(row, col_uid, str(user_id))
    ~~~~~~~~~~~~~~~~~^^^^^^^^^^^^^^^^^^^^^^^^^^^^
  File "/home/KamilSultan/.local/lib/python3.13/site-packages/gspread/worksheet.py", line 857, in update_cell
    data = self.spreadsheet.values_update(
        range_name,
        params={"valueInputOption": ValueInputOption.user_entered},
        body={"values": [[value]]},
    )
  File "/home/KamilSultan/.local/lib/python3.13/site-packages/gspread/spreadsheet.py", line 219, in values_update
    r = self.client.request("put", url, params=params, json=body)
  File "/home/KamilSultan/.local/lib/python3.13/site-packages/gspread/client.py", line 93, in request
    raise APIError(response)
gspread.exceptions.APIError: {'code': 403, 'message': 'The caller does not have permission', 'status': 'PERMISSION_DENIED'}
ERROR:root:[GoogleSheets] Ошибка записи сообщения: {'code': 403, 'message': 'The caller does not have permission', 'status': 'PERMISSION_DENIED'}
ERROR:telegram.ext.Application:No error handlers are registered, logging exception.
Traceback (most recent call last):
  File "/home/KamilSultan/.local/lib/python3.13/site-packages/telegram/ext/_application.py", line 1124, in process_update
    await coroutine
  File "/home/KamilSultan/.local/lib/python3.13/site-packages/telegram/ext/_conversationhandler.py", line 825, in handle_update
    new_state: object = await handler.handle_update(
                        ^^^^^^^^^^^^^^^^^^^^^^^^^^^^
        update, application, handler_check_result, context
        ^^^^^^^^^^^^^^^^^^^^^^^^^^^^^^^^^^^^^^^^^^^^^^^^^^
    )
    ^
  File "/home/KamilSultan/.local/lib/python3.13/site-packages/telegram/ext/_handler.py", line 141, in handle_update
    return await self.callback(update, context)
           ^^^^^^^^^^^^^^^^^^^^^^^^^^^^^^^^^^^^
  File "/home/KamilSultan/psych_bot/bot.py", line 56, in get_message1
    write_message(row, user_id, message, is_first=True)
    ~~~~~~~~~~~~~^^^^^^^^^^^^^^^^^^^^^^^^^^^^^^^^^^^^^^
  File "/home/KamilSultan/psych_bot/sheets.py", line 48, in write_message
    sheet.update_cell(row, col_uid, str(user_id))
    ~~~~~~~~~~~~~~~~~^^^^^^^^^^^^^^^^^^^^^^^^^^^^
  File "/home/KamilSultan/.local/lib/python3.13/site-packages/gspread/worksheet.py", line 857, in update_cell
    data = self.spreadsheet.values_update(
        range_name,
        params={"valueInputOption": ValueInputOption.user_entered},
        body={"values": [[value]]},
    )
  File "/home/KamilSultan/.local/lib/python3.13/site-packages/gspread/spreadsheet.py", line 219, in values_update
    r = self.client.request("put", url, params=params, json=body)
  File "/home/KamilSultan/.local/lib/python3.13/site-packages/gspread/client.py", line 93, in request
    raise APIError(response)
gspread.exceptions.APIError: {'code': 403, 'message': 'The caller does not have permission', 'status': 'PERMISSION_DENIED'}
ERROR:root:[GoogleSheets] Ошибка записи сообщения: {'code': 403, 'message': 'The caller does not have permission', 'status': 'PERMISSION_DENIED'}
ERROR:telegram.ext.Application:No error handlers are registered, logging exception.
Traceback (most recent call last):
  File "/home/KamilSultan/.local/lib/python3.13/site-packages/telegram/ext/_application.py", line 1124, in process_update
    await coroutine
  File "/home/KamilSultan/.local/lib/python3.13/site-packages/telegram/ext/_conversationhandler.py", line 825, in handle_update
    new_state: object = await handler.handle_update(
                        ^^^^^^^^^^^^^^^^^^^^^^^^^^^^
        update, application, handler_check_result, context
        ^^^^^^^^^^^^^^^^^^^^^^^^^^^^^^^^^^^^^^^^^^^^^^^^^^
    )
    ^
  File "/home/KamilSultan/.local/lib/python3.13/site-packages/telegram/ext/_handler.py", line 141, in handle_update
    return await self.callback(update, context)
           ^^^^^^^^^^^^^^^^^^^^^^^^^^^^^^^^^^^^
  File "/home/KamilSultan/psych_bot/bot.py", line 56, in get_message1
    message = update.message.text.strip()
  File "/home/KamilSultan/psych_bot/sheets.py", line 48, in write_message
    sheet.update_cell(row, col_uid, str(user_id))
    ~~~~~~~~~~~~~~~~~^^^^^^^^^^^^^^^^^^^^^^^^^^^^
  File "/home/KamilSultan/.local/lib/python3.13/site-packages/gspread/worksheet.py", line 857, in update_cell
    data = self.spreadsheet.values_update(
        range_name,
        params={"valueInputOption": ValueInputOption.user_entered},
        body={"values": [[value]]},
    )
  File "/home/KamilSultan/.local/lib/python3.13/site-packages/gspread/spreadsheet.py", line 219, in values_update
    r = self.client.request("put", url, params=params, json=body)
  File "/home/KamilSultan/.local/lib/python3.13/site-packages/gspread/client.py", line 93, in request
    raise APIError(response)
gspread.exceptions.APIError: {'code': 403, 'message': 'The caller does not have permission', 'status': 'PERMISSION_DENIED'}
ERROR:root:[GoogleSheets] Ошибка записи сообщения: {'code': 403, 'message': 'The caller does not have permission', 'status': 'PERMISSION_DENIED'}
ERROR:telegram.ext.Application:No error handlers are registered, logging exception.
Traceback (most recent call last):
  File "/home/KamilSultan/.local/lib/python3.13/site-packages/telegram/ext/_application.py", line 1124, in process_update
    await coroutine
  File "/home/KamilSultan/.local/lib/python3.13/site-packages/telegram/ext/_conversationhandler.py", line 825, in handle_update
    new_state: object = await handler.handle_update(
                        ^^^^^^^^^^^^^^^^^^^^^^^^^^^^
        update, application, handler_check_result, context
        ^^^^^^^^^^^^^^^^^^^^^^^^^^^^^^^^^^^^^^^^^^^^^^^^^^
    )
    ^
  File "/home/KamilSultan/.local/lib/python3.13/site-packages/telegram/ext/_handler.py", line 141, in handle_update
    return await self.callback(update, context)
           ^^^^^^^^^^^^^^^^^^^^^^^^^^^^^^^^^^^^
  File "/home/KamilSultan/psych_bot/bot.py", line 56, in get_message1
    row = session["row"]
  File "/home/KamilSultan/psych_bot/sheets.py", line 48, in write_message
    sheet.update_cell(row, col_uid, str(user_id))
    ~~~~~~~~~~~~~~~~~^^^^^^^^^^^^^^^^^^^^^^^^^^^^
  File "/home/KamilSultan/.local/lib/python3.13/site-packages/gspread/worksheet.py", line 857, in update_cell
    data = self.spreadsheet.values_update(
        range_name,
        params={"valueInputOption": ValueInputOption.user_entered},
        body={"values": [[value]]},
    )
  File "/home/KamilSultan/.local/lib/python3.13/site-packages/gspread/spreadsheet.py", line 219, in values_update
    r = self.client.request("put", url, params=params, json=body)
  File "/home/KamilSultan/.local/lib/python3.13/site-packages/gspread/client.py", line 93, in request
    raise APIError(response)
gspread.exceptions.APIError: {'code': 403, 'message': 'The caller does not have permission', 'status': 'PERMISSION_DENIED'}
ERROR:root:[GoogleSheets] Ошибка записи сообщения: {'code': 403, 'message': 'The caller does not have permission', 'status': 'PERMISSION_DENIED'}
ERROR:telegram.ext.Application:No error handlers are registered, logging exception.
Traceback (most recent call last):
  File "/home/KamilSultan/.local/lib/python3.13/site-packages/telegram/ext/_application.py", line 1124, in process_update
    await coroutine
  File "/home/KamilSultan/.local/lib/python3.13/site-packages/telegram/ext/_conversationhandler.py", line 825, in handle_update
    new_state: object = await handler.handle_update(
                        ^^^^^^^^^^^^^^^^^^^^^^^^^^^^
        update, application, handler_check_result, context
        ^^^^^^^^^^^^^^^^^^^^^^^^^^^^^^^^^^^^^^^^^^^^^^^^^^
    )
    ^
  File "/home/KamilSultan/.local/lib/python3.13/site-packages/telegram/ext/_handler.py", line 141, in handle_update
    return await self.callback(update, context)
           ^^^^^^^^^^^^^^^^^^^^^^^^^^^^^^^^^^^^
  File "/home/KamilSultan/psych_bot/bot.py", line 59, in get_message1
    write_message(row, user_id, message, is_first=True)
    ~~~~~~~~~~~~~^^^^^^^^^^^^^^^^^^^^^^^^^^^^^^^^^^^^^^
  File "/home/KamilSultan/psych_bot/sheets.py", line 48, in write_message
    sheet.update_cell(row, col_uid, str(user_id))
    ~~~~~~~~~~~~~~~~~^^^^^^^^^^^^^^^^^^^^^^^^^^^^
  File "/home/KamilSultan/.local/lib/python3.13/site-packages/gspread/worksheet.py", line 857, in update_cell
    data = self.spreadsheet.values_update(
        range_name,
        params={"valueInputOption": ValueInputOption.user_entered},
        body={"values": [[value]]},
    )
  File "/home/KamilSultan/.local/lib/python3.13/site-packages/gspread/spreadsheet.py", line 219, in values_update
    r = self.client.request("put", url, params=params, json=body)
  File "/home/KamilSultan/.local/lib/python3.13/site-packages/gspread/client.py", line 93, in request
    raise APIError(response)
gspread.exceptions.APIError: {'code': 403, 'message': 'The caller does not have permission', 'status': 'PERMISSION_DENIED'}
ERROR:root:[GoogleSheets] Ошибка записи сообщения: {'code': 403, 'message': 'The caller does not have permission', 'status': 'PERMISSION_DENIED'}
ERROR:telegram.ext.Application:No error handlers are registered, logging exception.
Traceback (most recent call last):
  File "/home/KamilSultan/.local/lib/python3.13/site-packages/telegram/ext/_application.py", line 1124, in process_update
    await coroutine
  File "/home/KamilSultan/.local/lib/python3.13/site-packages/telegram/ext/_conversationhandler.py", line 825, in handle_update
    new_state: object = await handler.handle_update(
                        ^^^^^^^^^^^^^^^^^^^^^^^^^^^^
        update, application, handler_check_result, context
        ^^^^^^^^^^^^^^^^^^^^^^^^^^^^^^^^^^^^^^^^^^^^^^^^^^
    )
    ^
  File "/home/KamilSultan/.local/lib/python3.13/site-packages/telegram/ext/_handler.py", line 141, in handle_update
    return await self.callback(update, context)
           ^^^^^^^^^^^^^^^^^^^^^^^^^^^^^^^^^^^^
  File "/home/KamilSultan/psych_bot/bot.py", line 59, in get_message1
    write_message(row, user_id, message, is_first=True)
    ~~~~~~~~~~~~~^^^^^^^^^^^^^^^^^^^^^^^^^^^^^^^^^^^^^^
  File "/home/KamilSultan/psych_bot/sheets.py", line 48, in write_message
    sheet.update_cell(row, col_uid, str(user_id))
    ~~~~~~~~~~~~~~~~~^^^^^^^^^^^^^^^^^^^^^^^^^^^^
  File "/home/KamilSultan/.local/lib/python3.13/site-packages/gspread/worksheet.py", line 857, in update_cell
    data = self.spreadsheet.values_update(
        range_name,
        params={"valueInputOption": ValueInputOption.user_entered},
        body={"values": [[value]]},
    )
  File "/home/KamilSultan/.local/lib/python3.13/site-packages/gspread/spreadsheet.py", line 219, in values_update
    r = self.client.request("put", url, params=params, json=body)
  File "/home/KamilSultan/.local/lib/python3.13/site-packages/gspread/client.py", line 93, in request
    raise APIError(response)
gspread.exceptions.APIError: {'code': 403, 'message': 'The caller does not have permission', 'status': 'PERMISSION_DENIED'}
ERROR:telegram.ext.Application:No error handlers are registered, logging exception.
Traceback (most recent call last):
  File "/home/KamilSultan/.local/lib/python3.13/site-packages/telegram/ext/_application.py", line 1124, in process_update
    await coroutine
  File "/home/KamilSultan/.local/lib/python3.13/site-packages/telegram/ext/_conversationhandler.py", line 825, in handle_update
    new_state: object = await handler.handle_update(
                        ^^^^^^^^^^^^^^^^^^^^^^^^^^^^
        update, application, handler_check_result, context
        ^^^^^^^^^^^^^^^^^^^^^^^^^^^^^^^^^^^^^^^^^^^^^^^^^^
    )
    ^
  File "/home/KamilSultan/.local/lib/python3.13/site-packages/telegram/ext/_handler.py", line 141, in handle_update
    return await self.callback(update, context)
           ^^^^^^^^^^^^^^^^^^^^^^^^^^^^^^^^^^^^
  File "/home/KamilSultan/psych_bot/bot.py", line 60, in get_message1
    reset()
    ~~~~~^^
TypeError: reset() missing 2 required positional arguments: 'update' and 'context'
ERROR:telegram.ext.Application:No error handlers are registered, logging exception.
Traceback (most recent call last):
  File "/home/KamilSultan/.local/lib/python3.13/site-packages/telegram/ext/_application.py", line 1124, in process_update
    await coroutine
  File "/home/KamilSultan/.local/lib/python3.13/site-packages/telegram/ext/_conversationhandler.py", line 825, in handle_update
    new_state: object = await handler.handle_update(
                        ^^^^^^^^^^^^^^^^^^^^^^^^^^^^
        update, application, handler_check_result, context
        ^^^^^^^^^^^^^^^^^^^^^^^^^^^^^^^^^^^^^^^^^^^^^^^^^^
    )
    ^
  File "/home/KamilSultan/.local/lib/python3.13/site-packages/telegram/ext/_handler.py", line 141, in handle_update
    return await self.callback(update, context)
           ^^^^^^^^^^^^^^^^^^^^^^^^^^^^^^^^^^^^
  File "/home/KamilSultan/psych_bot/bot.py", line 60, in get_message1
    reset()
    ~~~~~^^
TypeError: reset() missing 2 required positional arguments: 'update' and 'context'
ERROR:telegram.ext.Application:No error handlers are registered, logging exception.
Traceback (most recent call last):
  File "/home/KamilSultan/.local/lib/python3.13/site-packages/telegram/ext/_application.py", line 1124, in process_update
    await coroutine
  File "/home/KamilSultan/.local/lib/python3.13/site-packages/telegram/ext/_conversationhandler.py", line 825, in handle_update
    new_state: object = await handler.handle_update(
                        ^^^^^^^^^^^^^^^^^^^^^^^^^^^^
        update, application, handler_check_result, context
        ^^^^^^^^^^^^^^^^^^^^^^^^^^^^^^^^^^^^^^^^^^^^^^^^^^
    )
    ^
  File "/home/KamilSultan/.local/lib/python3.13/site-packages/telegram/ext/_handler.py", line 141, in handle_update
    return await self.callback(update, context)
           ^^^^^^^^^^^^^^^^^^^^^^^^^^^^^^^^^^^^
  File "/home/KamilSultan/psych_bot/bot.py", line 60, in get_message1
    reset()
    ~~~~~^^
TypeError: reset() missing 2 required positional arguments: 'update' and 'context'
ERROR:telegram.ext.Application:No error handlers are registered, logging exception.
Traceback (most recent call last):
  File "/home/KamilSultan/.local/lib/python3.13/site-packages/telegram/ext/_application.py", line 1124, in process_update
    await coroutine
  File "/home/KamilSultan/.local/lib/python3.13/site-packages/telegram/ext/_conversationhandler.py", line 825, in handle_update
    new_state: object = await handler.handle_update(
                        ^^^^^^^^^^^^^^^^^^^^^^^^^^^^
        update, application, handler_check_result, context
        ^^^^^^^^^^^^^^^^^^^^^^^^^^^^^^^^^^^^^^^^^^^^^^^^^^
    )
    ^
  File "/home/KamilSultan/.local/lib/python3.13/site-packages/telegram/ext/_handler.py", line 141, in handle_update
    return await self.callback(update, context)
           ^^^^^^^^^^^^^^^^^^^^^^^^^^^^^^^^^^^^
  File "/home/KamilSultan/psych_bot/bot.py", line 60, in get_message1
    reset()
    ~~~~~^^
TypeError: reset() missing 2 required positional arguments: 'update' and 'context'
ERROR:telegram.ext.Application:No error handlers are registered, logging exception.
Traceback (most recent call last):
  File "/home/KamilSultan/.local/lib/python3.13/site-packages/telegram/ext/_application.py", line 1124, in process_update
    await coroutine
  File "/home/KamilSultan/.local/lib/python3.13/site-packages/telegram/ext/_conversationhandler.py", line 825, in handle_update
    new_state: object = await handler.handle_update(
                        ^^^^^^^^^^^^^^^^^^^^^^^^^^^^
        update, application, handler_check_result, context
        ^^^^^^^^^^^^^^^^^^^^^^^^^^^^^^^^^^^^^^^^^^^^^^^^^^
    )
    ^
  File "/home/KamilSultan/.local/lib/python3.13/site-packages/telegram/ext/_handler.py", line 141, in handle_update
    return await self.callback(update, context)
           ^^^^^^^^^^^^^^^^^^^^^^^^^^^^^^^^^^^^
  File "/home/KamilSultan/psych_bot/bot.py", line 60, in get_message1
    reset()
    ~~~~~^^
TypeError: reset() missing 2 required positional arguments: 'update' and 'context'
ERROR:root:[GoogleSheets] Ошибка записи сообщения: {'code': 403, 'message': 'The caller does not have permission', 'status': 'PERMISSION_DENIED'}
ERROR:telegram.ext.Application:No error handlers are registered, logging exception.
Traceback (most recent call last):
  File "/home/KamilSultan/.local/lib/python3.13/site-packages/telegram/ext/_application.py", line 1124, in process_update
    await coroutine
  File "/home/KamilSultan/.local/lib/python3.13/site-packages/telegram/ext/_conversationhandler.py", line 825, in handle_update
    new_state: object = await handler.handle_update(
                        ^^^^^^^^^^^^^^^^^^^^^^^^^^^^
        update, application, handler_check_result, context
        ^^^^^^^^^^^^^^^^^^^^^^^^^^^^^^^^^^^^^^^^^^^^^^^^^^
    )
    ^
  File "/home/KamilSultan/.local/lib/python3.13/site-packages/telegram/ext/_handler.py", line 141, in handle_update
    return await self.callback(update, context)
           ^^^^^^^^^^^^^^^^^^^^^^^^^^^^^^^^^^^^
  File "/home/KamilSultan/psych_bot/bot.py", line 63, in get_message1
    write_message(row, user_id, message, is_first=True)
    ~~~~~~~~~~~~~^^^^^^^^^^^^^^^^^^^^^^^^^^^^^^^^^^^^^^
  File "/home/KamilSultan/psych_bot/sheets.py", line 48, in write_message
    sheet.update_cell(row, col_uid, str(user_id))
    ~~~~~~~~~~~~~~~~~^^^^^^^^^^^^^^^^^^^^^^^^^^^^
  File "/home/KamilSultan/.local/lib/python3.13/site-packages/gspread/worksheet.py", line 857, in update_cell
    data = self.spreadsheet.values_update(
        range_name,
        params={"valueInputOption": ValueInputOption.user_entered},
        body={"values": [[value]]},
    )
  File "/home/KamilSultan/.local/lib/python3.13/site-packages/gspread/spreadsheet.py", line 219, in values_update
    r = self.client.request("put", url, params=params, json=body)
  File "/home/KamilSultan/.local/lib/python3.13/site-packages/gspread/client.py", line 93, in request
    raise APIError(response)
gspread.exceptions.APIError: {'code': 403, 'message': 'The caller does not have permission', 'status': 'PERMISSION_DENIED'}
ERROR:root:[GoogleSheets] Ошибка записи сообщения: {'code': 403, 'message': 'The caller does not have permission', 'status': 'PERMISSION_DENIED'}
ERROR:telegram.ext.Application:No error handlers are registered, logging exception.
Traceback (most recent call last):
  File "/home/KamilSultan/.local/lib/python3.13/site-packages/telegram/ext/_application.py", line 1124, in process_update
    await coroutine
  File "/home/KamilSultan/.local/lib/python3.13/site-packages/telegram/ext/_conversationhandler.py", line 825, in handle_update
    new_state: object = await handler.handle_update(
                        ^^^^^^^^^^^^^^^^^^^^^^^^^^^^
        update, application, handler_check_result, context
        ^^^^^^^^^^^^^^^^^^^^^^^^^^^^^^^^^^^^^^^^^^^^^^^^^^
    )
    ^
  File "/home/KamilSultan/.local/lib/python3.13/site-packages/telegram/ext/_handler.py", line 141, in handle_update
    return await self.callback(update, context)
           ^^^^^^^^^^^^^^^^^^^^^^^^^^^^^^^^^^^^
  File "/home/KamilSultan/psych_bot/bot.py", line 63, in get_message1
    write_message(row, user_id, message, is_first=True)
    ~~~~~~~~~~~~~^^^^^^^^^^^^^^^^^^^^^^^^^^^^^^^^^^^^^^
  File "/home/KamilSultan/psych_bot/sheets.py", line 48, in write_message
    sheet.update_cell(row, col_uid, str(user_id))
    ~~~~~~~~~~~~~~~~~^^^^^^^^^^^^^^^^^^^^^^^^^^^^
  File "/home/KamilSultan/.local/lib/python3.13/site-packages/gspread/worksheet.py", line 857, in update_cell
    data = self.spreadsheet.values_update(
        range_name,
        params={"valueInputOption": ValueInputOption.user_entered},
        body={"values": [[value]]},
    )
  File "/home/KamilSultan/.local/lib/python3.13/site-packages/gspread/spreadsheet.py", line 219, in values_update
    r = self.client.request("put", url, params=params, json=body)
  File "/home/KamilSultan/.local/lib/python3.13/site-packages/gspread/client.py", line 93, in request
    raise APIError(response)
gspread.exceptions.APIError: {'code': 403, 'message': 'The caller does not have permission', 'status': 'PERMISSION_DENIED'}
ERROR:root:[GoogleSheets] Ошибка записи сообщения: {'code': 403, 'message': 'The caller does not have permission', 'status': 'PERMISSION_DENIED'}
ERROR:telegram.ext.Application:No error handlers are registered, logging exception.
Traceback (most recent call last):
  File "/home/KamilSultan/.local/lib/python3.13/site-packages/telegram/ext/_application.py", line 1124, in process_update
    await coroutine
  File "/home/KamilSultan/.local/lib/python3.13/site-packages/telegram/ext/_conversationhandler.py", line 825, in handle_update
    new_state: object = await handler.handle_update(
                        ^^^^^^^^^^^^^^^^^^^^^^^^^^^^
        update, application, handler_check_result, context
        ^^^^^^^^^^^^^^^^^^^^^^^^^^^^^^^^^^^^^^^^^^^^^^^^^^
    )
    ^
  File "/home/KamilSultan/.local/lib/python3.13/site-packages/telegram/ext/_handler.py", line 141, in handle_update
    return await self.callback(update, context)
           ^^^^^^^^^^^^^^^^^^^^^^^^^^^^^^^^^^^^
  File "/home/KamilSultan/psych_bot/bot.py", line 63, in get_message1
    write_message(row, user_id, message, is_first=True)
    ~~~~~~~~~~~~~^^^^^^^^^^^^^^^^^^^^^^^^^^^^^^^^^^^^^^
  File "/home/KamilSultan/psych_bot/sheets.py", line 48, in write_message
    sheet.update_cell(row, col_uid, str(user_id))
    ~~~~~~~~~~~~~~~~~^^^^^^^^^^^^^^^^^^^^^^^^^^^^
  File "/home/KamilSultan/.local/lib/python3.13/site-packages/gspread/worksheet.py", line 857, in update_cell
    data = self.spreadsheet.values_update(
        range_name,
        params={"valueInputOption": ValueInputOption.user_entered},
        body={"values": [[value]]},
    )
  File "/home/KamilSultan/.local/lib/python3.13/site-packages/gspread/spreadsheet.py", line 219, in values_update
    r = self.client.request("put", url, params=params, json=body)
  File "/home/KamilSultan/.local/lib/python3.13/site-packages/gspread/client.py", line 93, in request
    raise APIError(response)
gspread.exceptions.APIError: {'code': 403, 'message': 'The caller does not have permission', 'status': 'PERMISSION_DENIED'}
ERROR:telegram.ext.Application:No error handlers are registered, logging exception.
Traceback (most recent call last):
  File "/home/KamilSultan/.local/lib/python3.13/site-packages/telegram/ext/_application.py", line 1124, in process_update
    await coroutine
  File "/home/KamilSultan/.local/lib/python3.13/site-packages/telegram/ext/_conversationhandler.py", line 825, in handle_update
    new_state: object = await handler.handle_update(
                        ^^^^^^^^^^^^^^^^^^^^^^^^^^^^
        update, application, handler_check_result, context
        ^^^^^^^^^^^^^^^^^^^^^^^^^^^^^^^^^^^^^^^^^^^^^^^^^^
    )
    ^
  File "/home/KamilSultan/.local/lib/python3.13/site-packages/telegram/ext/_handler.py", line 141, in handle_update
    return await self.callback(update, context)
           ^^^^^^^^^^^^^^^^^^^^^^^^^^^^^^^^^^^^
  File "/home/KamilSultan/psych_bot/bot.py", line 60, in get_message1
    reset()
    ~~~~~^^
TypeError: reset() missing 2 required positional arguments: 'update' and 'context'
ERROR:telegram.ext.Application:No error handlers are registered, logging exception.
Traceback (most recent call last):
  File "/home/KamilSultan/.local/lib/python3.13/site-packages/telegram/ext/_application.py", line 1124, in process_update
    await coroutine
  File "/home/KamilSultan/.local/lib/python3.13/site-packages/telegram/ext/_conversationhandler.py", line 825, in handle_update
    new_state: object = await handler.handle_update(
                        ^^^^^^^^^^^^^^^^^^^^^^^^^^^^
        update, application, handler_check_result, context
        ^^^^^^^^^^^^^^^^^^^^^^^^^^^^^^^^^^^^^^^^^^^^^^^^^^
    )
    ^
  File "/home/KamilSultan/.local/lib/python3.13/site-packages/telegram/ext/_handler.py", line 141, in handle_update
    return await self.callback(update, context)
           ^^^^^^^^^^^^^^^^^^^^^^^^^^^^^^^^^^^^
  File "/home/KamilSultan/psych_bot/bot.py", line 60, in get_message1
    reset()
    ~~~~~^^
TypeError: reset() missing 2 required positional arguments: 'update' and 'context'
ERROR:root:[GoogleSheets] Ошибка записи сообщения: {'code': 403, 'message': 'The caller does not have permission', 'status': 'PERMISSION_DENIED'}
ERROR:telegram.ext.Application:No error handlers are registered, logging exception.
Traceback (most recent call last):
  File "/home/KamilSultan/.local/lib/python3.13/site-packages/telegram/ext/_application.py", line 1124, in process_update
    await coroutine
  File "/home/KamilSultan/.local/lib/python3.13/site-packages/telegram/ext/_conversationhandler.py", line 825, in handle_update
    new_state: object = await handler.handle_update(
                        ^^^^^^^^^^^^^^^^^^^^^^^^^^^^
        update, application, handler_check_result, context
        ^^^^^^^^^^^^^^^^^^^^^^^^^^^^^^^^^^^^^^^^^^^^^^^^^^
    )
    ^
  File "/home/KamilSultan/.local/lib/python3.13/site-packages/telegram/ext/_handler.py", line 141, in handle_update
    return await self.callback(update, context)
           ^^^^^^^^^^^^^^^^^^^^^^^^^^^^^^^^^^^^
  File "/home/KamilSultan/psych_bot/bot.py", line 63, in get_message1
    write_message(row, user_id, message, is_first=True)
    ~~~~~~~~~~~~~^^^^^^^^^^^^^^^^^^^^^^^^^^^^^^^^^^^^^^
  File "/home/KamilSultan/psych_bot/sheets.py", line 48, in write_message
    sheet.update_cell(row, col_uid, str(user_id))
    ~~~~~~~~~~~~~~~~~^^^^^^^^^^^^^^^^^^^^^^^^^^^^
  File "/home/KamilSultan/.local/lib/python3.13/site-packages/gspread/worksheet.py", line 857, in update_cell
    data = self.spreadsheet.values_update(
        range_name,
        params={"valueInputOption": ValueInputOption.user_entered},
        body={"values": [[value]]},
    )
  File "/home/KamilSultan/.local/lib/python3.13/site-packages/gspread/spreadsheet.py", line 219, in values_update
    r = self.client.request("put", url, params=params, json=body)
  File "/home/KamilSultan/.local/lib/python3.13/site-packages/gspread/client.py", line 93, in request
    raise APIError(response)
gspread.exceptions.APIError: {'code': 403, 'message': 'The caller does not have permission', 'status': 'PERMISSION_DENIED'}
ERROR:telegram.ext.Application:No error handlers are registered, logging exception.
Traceback (most recent call last):
  File "/home/KamilSultan/.local/lib/python3.13/site-packages/telegram/ext/_application.py", line 1124, in process_update
    await coroutine
  File "/home/KamilSultan/.local/lib/python3.13/site-packages/telegram/ext/_conversationhandler.py", line 825, in handle_update
    new_state: object = await handler.handle_update(
                        ^^^^^^^^^^^^^^^^^^^^^^^^^^^^
        update, application, handler_check_result, context
        ^^^^^^^^^^^^^^^^^^^^^^^^^^^^^^^^^^^^^^^^^^^^^^^^^^
    )
    ^
  File "/home/KamilSultan/.local/lib/python3.13/site-packages/telegram/ext/_handler.py", line 141, in handle_update
    return await self.callback(update, context)
           ^^^^^^^^^^^^^^^^^^^^^^^^^^^^^^^^^^^^
  File "/home/KamilSultan/psych_bot/bot.py", line 51, in choose_device
    if session["device"] is None:
       ~~~~~~~^^^^^^^^^^
KeyError: 'device'
ERROR:root:[GoogleSheets] Ошибка записи сообщения: {'code': 403, 'message': 'The caller does not have permission', 'status': 'PERMISSION_DENIED'}
ERROR:telegram.ext.Application:No error handlers are registered, logging exception.
Traceback (most recent call last):
  File "/home/KamilSultan/.local/lib/python3.13/site-packages/telegram/ext/_application.py", line 1124, in process_update
    await coroutine
  File "/home/KamilSultan/.local/lib/python3.13/site-packages/telegram/ext/_conversationhandler.py", line 825, in handle_update
    new_state: object = await handler.handle_update(
                        ^^^^^^^^^^^^^^^^^^^^^^^^^^^^
        update, application, handler_check_result, context
        ^^^^^^^^^^^^^^^^^^^^^^^^^^^^^^^^^^^^^^^^^^^^^^^^^^
    )
    ^
  File "/home/KamilSultan/.local/lib/python3.13/site-packages/telegram/ext/_handler.py", line 141, in handle_update
    return await self.callback(update, context)
           ^^^^^^^^^^^^^^^^^^^^^^^^^^^^^^^^^^^^
  File "/home/KamilSultan/psych_bot/bot.py", line 70, in get_message1
    write_message(row, user_id, message, is_first=True)
    ~~~~~~~~~~~~~^^^^^^^^^^^^^^^^^^^^^^^^^^^^^^^^^^^^^^
  File "/home/KamilSultan/psych_bot/sheets.py", line 48, in write_message
    sheet.update_cell(row, col_uid, str(user_id))
    ~~~~~~~~~~~~~~~~~^^^^^^^^^^^^^^^^^^^^^^^^^^^^
  File "/home/KamilSultan/.local/lib/python3.13/site-packages/gspread/worksheet.py", line 857, in update_cell
    data = self.spreadsheet.values_update(
        range_name,
        params={"valueInputOption": ValueInputOption.user_entered},
        body={"values": [[value]]},
    )
  File "/home/KamilSultan/.local/lib/python3.13/site-packages/gspread/spreadsheet.py", line 219, in values_update
    r = self.client.request("put", url, params=params, json=body)
  File "/home/KamilSultan/.local/lib/python3.13/site-packages/gspread/client.py", line 93, in request
    raise APIError(response)
gspread.exceptions.APIError: {'code': 403, 'message': 'The caller does not have permission', 'status': 'PERMISSION_DENIED'}
ERROR:root:[GoogleSheets] Ошибка записи сообщения: {'code': 403, 'message': 'The caller does not have permission', 'status': 'PERMISSION_DENIED'}
ERROR:telegram.ext.Application:No error handlers are registered, logging exception.
Traceback (most recent call last):
  File "/home/KamilSultan/.local/lib/python3.13/site-packages/telegram/ext/_application.py", line 1124, in process_update
    await coroutine
  File "/home/KamilSultan/.local/lib/python3.13/site-packages/telegram/ext/_conversationhandler.py", line 825, in handle_update
    new_state: object = await handler.handle_update(
                        ^^^^^^^^^^^^^^^^^^^^^^^^^^^^
        update, application, handler_check_result, context
        ^^^^^^^^^^^^^^^^^^^^^^^^^^^^^^^^^^^^^^^^^^^^^^^^^^
    )
    ^
  File "/home/KamilSultan/.local/lib/python3.13/site-packages/telegram/ext/_handler.py", line 141, in handle_update
    return await self.callback(update, context)
           ^^^^^^^^^^^^^^^^^^^^^^^^^^^^^^^^^^^^
  File "/home/KamilSultan/psych_bot/bot.py", line 70, in get_message1
    write_message(row, user_id, message, is_first=True)
    ~~~~~~~~~~~~~^^^^^^^^^^^^^^^^^^^^^^^^^^^^^^^^^^^^^^
  File "/home/KamilSultan/psych_bot/sheets.py", line 48, in write_message
    sheet.update_cell(row, col_uid, str(user_id))
    ~~~~~~~~~~~~~~~~~^^^^^^^^^^^^^^^^^^^^^^^^^^^^
  File "/home/KamilSultan/.local/lib/python3.13/site-packages/gspread/worksheet.py", line 857, in update_cell
    data = self.spreadsheet.values_update(
        range_name,
        params={"valueInputOption": ValueInputOption.user_entered},
        body={"values": [[value]]},
    )
  File "/home/KamilSultan/.local/lib/python3.13/site-packages/gspread/spreadsheet.py", line 219, in values_update
    r = self.client.request("put", url, params=params, json=body)
  File "/home/KamilSultan/.local/lib/python3.13/site-packages/gspread/client.py", line 93, in request
    raise APIError(response)
gspread.exceptions.APIError: {'code': 403, 'message': 'The caller does not have permission', 'status': 'PERMISSION_DENIED'}
ERROR:root:[GoogleSheets] Ошибка записи сообщения: {'code': 403, 'message': 'The caller does not have permission', 'status': 'PERMISSION_DENIED'}
ERROR:telegram.ext.Application:No error handlers are registered, logging exception.
Traceback (most recent call last):
  File "/home/KamilSultan/.local/lib/python3.13/site-packages/telegram/ext/_application.py", line 1124, in process_update
    await coroutine
  File "/home/KamilSultan/.local/lib/python3.13/site-packages/telegram/ext/_conversationhandler.py", line 825, in handle_update
    new_state: object = await handler.handle_update(
                        ^^^^^^^^^^^^^^^^^^^^^^^^^^^^
        update, application, handler_check_result, context
        ^^^^^^^^^^^^^^^^^^^^^^^^^^^^^^^^^^^^^^^^^^^^^^^^^^
    )
    ^
  File "/home/KamilSultan/.local/lib/python3.13/site-packages/telegram/ext/_handler.py", line 141, in handle_update
    return await self.callback(update, context)
           ^^^^^^^^^^^^^^^^^^^^^^^^^^^^^^^^^^^^
  File "/home/KamilSultan/psych_bot/bot.py", line 70, in get_message1
    write_message(row, user_id, message, is_first=True)
    ~~~~~~~~~~~~~^^^^^^^^^^^^^^^^^^^^^^^^^^^^^^^^^^^^^^
  File "/home/KamilSultan/psych_bot/sheets.py", line 48, in write_message
    sheet.update_cell(row, col_uid, str(user_id))
    ~~~~~~~~~~~~~~~~~^^^^^^^^^^^^^^^^^^^^^^^^^^^^
  File "/home/KamilSultan/.local/lib/python3.13/site-packages/gspread/worksheet.py", line 857, in update_cell
    data = self.spreadsheet.values_update(
        range_name,
        params={"valueInputOption": ValueInputOption.user_entered},
        body={"values": [[value]]},
    )
  File "/home/KamilSultan/.local/lib/python3.13/site-packages/gspread/spreadsheet.py", line 219, in values_update
    r = self.client.request("put", url, params=params, json=body)
  File "/home/KamilSultan/.local/lib/python3.13/site-packages/gspread/client.py", line 93, in request
    raise APIError(response)
gspread.exceptions.APIError: {'code': 403, 'message': 'The caller does not have permission', 'status': 'PERMISSION_DENIED'}
ERROR:root:[GoogleSheets] Ошибка записи сообщения: {'code': 403, 'message': 'The caller does not have permission', 'status': 'PERMISSION_DENIED'}
ERROR:telegram.ext.Application:No error handlers are registered, logging exception.
Traceback (most recent call last):
  File "/home/KamilSultan/.local/lib/python3.13/site-packages/telegram/ext/_application.py", line 1124, in process_update
    await coroutine
  File "/home/KamilSultan/.local/lib/python3.13/site-packages/telegram/ext/_conversationhandler.py", line 825, in handle_update
    new_state: object = await handler.handle_update(
                        ^^^^^^^^^^^^^^^^^^^^^^^^^^^^
        update, application, handler_check_result, context
        ^^^^^^^^^^^^^^^^^^^^^^^^^^^^^^^^^^^^^^^^^^^^^^^^^^
    )
    ^
  File "/home/KamilSultan/.local/lib/python3.13/site-packages/telegram/ext/_handler.py", line 141, in handle_update
    return await self.callback(update, context)
           ^^^^^^^^^^^^^^^^^^^^^^^^^^^^^^^^^^^^
  File "/home/KamilSultan/psych_bot/bot.py", line 69, in get_message1
    write_message(row, user_id, message, is_first=True)
    ~~~~~~~~~~~~~^^^^^^^^^^^^^^^^^^^^^^^^^^^^^^^^^^^^^^
  File "/home/KamilSultan/psych_bot/sheets.py", line 48, in write_message
    sheet.update_cell(row, col_uid, str(user_id))
    ~~~~~~~~~~~~~~~~~^^^^^^^^^^^^^^^^^^^^^^^^^^^^
  File "/home/KamilSultan/.local/lib/python3.13/site-packages/gspread/worksheet.py", line 857, in update_cell
    data = self.spreadsheet.values_update(
        range_name,
        params={"valueInputOption": ValueInputOption.user_entered},
        body={"values": [[value]]},
    )
  File "/home/KamilSultan/.local/lib/python3.13/site-packages/gspread/spreadsheet.py", line 219, in values_update
    r = self.client.request("put", url, params=params, json=body)
  File "/home/KamilSultan/.local/lib/python3.13/site-packages/gspread/client.py", line 93, in request
    raise APIError(response)
gspread.exceptions.APIError: {'code': 403, 'message': 'The caller does not have permission', 'status': 'PERMISSION_DENIED'}
ERROR:root:[GoogleSheets] Ошибка записи сообщения: {'code': 403, 'message': 'The caller does not have permission', 'status': 'PERMISSION_DENIED'}
ERROR:telegram.ext.Application:No error handlers are registered, logging exception.
Traceback (most recent call last):
  File "/home/KamilSultan/.local/lib/python3.13/site-packages/telegram/ext/_application.py", line 1124, in process_update
    await coroutine
  File "/home/KamilSultan/.local/lib/python3.13/site-packages/telegram/ext/_conversationhandler.py", line 825, in handle_update
    new_state: object = await handler.handle_update(
                        ^^^^^^^^^^^^^^^^^^^^^^^^^^^^
        update, application, handler_check_result, context
        ^^^^^^^^^^^^^^^^^^^^^^^^^^^^^^^^^^^^^^^^^^^^^^^^^^
    )
    ^
  File "/home/KamilSultan/.local/lib/python3.13/site-packages/telegram/ext/_handler.py", line 141, in handle_update
    return await self.callback(update, context)
           ^^^^^^^^^^^^^^^^^^^^^^^^^^^^^^^^^^^^
  File "/home/KamilSultan/psych_bot/bot.py", line 69, in get_message1
    write_message(row, user_id, message, is_first=True)
    ~~~~~~~~~~~~~^^^^^^^^^^^^^^^^^^^^^^^^^^^^^^^^^^^^^^
  File "/home/KamilSultan/psych_bot/sheets.py", line 48, in write_message
    sheet.update_cell(row, col_uid, str(user_id))
    ~~~~~~~~~~~~~~~~~^^^^^^^^^^^^^^^^^^^^^^^^^^^^
  File "/home/KamilSultan/.local/lib/python3.13/site-packages/gspread/worksheet.py", line 857, in update_cell
    data = self.spreadsheet.values_update(
        range_name,
        params={"valueInputOption": ValueInputOption.user_entered},
        body={"values": [[value]]},
    )
  File "/home/KamilSultan/.local/lib/python3.13/site-packages/gspread/spreadsheet.py", line 219, in values_update
    r = self.client.request("put", url, params=params, json=body)
  File "/home/KamilSultan/.local/lib/python3.13/site-packages/gspread/client.py", line 93, in request
    raise APIError(response)
gspread.exceptions.APIError: {'code': 403, 'message': 'The caller does not have permission', 'status': 'PERMISSION_DENIED'}
ERROR:root:[GoogleSheets] Ошибка записи сообщения: {'code': 403, 'message': 'The caller does not have permission', 'status': 'PERMISSION_DENIED'}
ERROR:telegram.ext.Application:No error handlers are registered, logging exception.
Traceback (most recent call last):
  File "/home/KamilSultan/.local/lib/python3.13/site-packages/telegram/ext/_application.py", line 1124, in process_update
    await coroutine
  File "/home/KamilSultan/.local/lib/python3.13/site-packages/telegram/ext/_conversationhandler.py", line 825, in handle_update
    new_state: object = await handler.handle_update(
                        ^^^^^^^^^^^^^^^^^^^^^^^^^^^^
        update, application, handler_check_result, context
        ^^^^^^^^^^^^^^^^^^^^^^^^^^^^^^^^^^^^^^^^^^^^^^^^^^
    )
    ^
  File "/home/KamilSultan/.local/lib/python3.13/site-packages/telegram/ext/_handler.py", line 141, in handle_update
    return await self.callback(update, context)
           ^^^^^^^^^^^^^^^^^^^^^^^^^^^^^^^^^^^^
  File "/home/KamilSultan/psych_bot/bot.py", line 69, in get_message1
    write_message(row, user_id, message, is_first=True)
    ~~~~~~~~~~~~~^^^^^^^^^^^^^^^^^^^^^^^^^^^^^^^^^^^^^^
  File "/home/KamilSultan/psych_bot/sheets.py", line 48, in write_message
    sheet.update_cell(row, col_uid, str(user_id))
    ~~~~~~~~~~~~~~~~~^^^^^^^^^^^^^^^^^^^^^^^^^^^^
  File "/home/KamilSultan/.local/lib/python3.13/site-packages/gspread/worksheet.py", line 857, in update_cell
    data = self.spreadsheet.values_update(
        range_name,
        params={"valueInputOption": ValueInputOption.user_entered},
        body={"values": [[value]]},
    )
  File "/home/KamilSultan/.local/lib/python3.13/site-packages/gspread/spreadsheet.py", line 219, in values_update
    r = self.client.request("put", url, params=params, json=body)
  File "/home/KamilSultan/.local/lib/python3.13/site-packages/gspread/client.py", line 93, in request
    raise APIError(response)
gspread.exceptions.APIError: {'code': 403, 'message': 'The caller does not have permission', 'status': 'PERMISSION_DENIED'}
ERROR:root:[GoogleSheets] Ошибка записи сообщения: {'code': 403, 'message': 'The caller does not have permission', 'status': 'PERMISSION_DENIED'}
ERROR:telegram.ext.Application:No error handlers are registered, logging exception.
Traceback (most recent call last):
  File "/home/KamilSultan/.local/lib/python3.13/site-packages/telegram/ext/_application.py", line 1124, in process_update
    await coroutine
  File "/home/KamilSultan/.local/lib/python3.13/site-packages/telegram/ext/_conversationhandler.py", line 825, in handle_update
    new_state: object = await handler.handle_update(
                        ^^^^^^^^^^^^^^^^^^^^^^^^^^^^
        update, application, handler_check_result, context
        ^^^^^^^^^^^^^^^^^^^^^^^^^^^^^^^^^^^^^^^^^^^^^^^^^^
    )
    ^
  File "/home/KamilSultan/.local/lib/python3.13/site-packages/telegram/ext/_handler.py", line 141, in handle_update
    return await self.callback(update, context)
           ^^^^^^^^^^^^^^^^^^^^^^^^^^^^^^^^^^^^
  File "/home/KamilSultan/psych_bot/bot.py", line 69, in get_message1
    write_message(row, user_id, message, is_first=True)
    ~~~~~~~~~~~~~^^^^^^^^^^^^^^^^^^^^^^^^^^^^^^^^^^^^^^
  File "/home/KamilSultan/psych_bot/sheets.py", line 48, in write_message
    sheet.update_cell(row, col_uid, str(user_id))
    ~~~~~~~~~~~~~~~~~^^^^^^^^^^^^^^^^^^^^^^^^^^^^
  File "/home/KamilSultan/.local/lib/python3.13/site-packages/gspread/worksheet.py", line 857, in update_cell
    data = self.spreadsheet.values_update(
        range_name,
        params={"valueInputOption": ValueInputOption.user_entered},
        body={"values": [[value]]},
    )
  File "/home/KamilSultan/.local/lib/python3.13/site-packages/gspread/spreadsheet.py", line 219, in values_update
    r = self.client.request("put", url, params=params, json=body)
  File "/home/KamilSultan/.local/lib/python3.13/site-packages/gspread/client.py", line 93, in request
    raise APIError(response)
gspread.exceptions.APIError: {'code': 403, 'message': 'The caller does not have permission', 'status': 'PERMISSION_DENIED'}
ERROR:root:[GoogleSheets] Ошибка записи сообщения: {'code': 403, 'message': 'The caller does not have permission', 'status': 'PERMISSION_DENIED'}
ERROR:telegram.ext.Application:No error handlers are registered, logging exception.
Traceback (most recent call last):
  File "/home/KamilSultan/.local/lib/python3.13/site-packages/telegram/ext/_application.py", line 1124, in process_update
    await coroutine
  File "/home/KamilSultan/.local/lib/python3.13/site-packages/telegram/ext/_conversationhandler.py", line 825, in handle_update
    new_state: object = await handler.handle_update(
                        ^^^^^^^^^^^^^^^^^^^^^^^^^^^^
        update, application, handler_check_result, context
        ^^^^^^^^^^^^^^^^^^^^^^^^^^^^^^^^^^^^^^^^^^^^^^^^^^
    )
    ^
  File "/home/KamilSultan/.local/lib/python3.13/site-packages/telegram/ext/_handler.py", line 141, in handle_update
    return await self.callback(update, context)
           ^^^^^^^^^^^^^^^^^^^^^^^^^^^^^^^^^^^^
  File "/home/KamilSultan/psych_bot/bot.py", line 69, in get_message1
    write_message(row, user_id, message, is_first=True)
    ~~~~~~~~~~~~~^^^^^^^^^^^^^^^^^^^^^^^^^^^^^^^^^^^^^^
  File "/home/KamilSultan/psych_bot/sheets.py", line 48, in write_message
    sheet.update_cell(row, col_uid, str(user_id))
    ~~~~~~~~~~~~~~~~~^^^^^^^^^^^^^^^^^^^^^^^^^^^^
  File "/home/KamilSultan/.local/lib/python3.13/site-packages/gspread/worksheet.py", line 857, in update_cell
    data = self.spreadsheet.values_update(
        range_name,
        params={"valueInputOption": ValueInputOption.user_entered},
        body={"values": [[value]]},
    )
  File "/home/KamilSultan/.local/lib/python3.13/site-packages/gspread/spreadsheet.py", line 219, in values_update
    r = self.client.request("put", url, params=params, json=body)
  File "/home/KamilSultan/.local/lib/python3.13/site-packages/gspread/client.py", line 93, in request
    raise APIError(response)
gspread.exceptions.APIError: {'code': 403, 'message': 'The caller does not have permission', 'status': 'PERMISSION_DENIED'}
ERROR:root:[GoogleSheets] Ошибка записи сообщения: {'code': 403, 'message': 'The caller does not have permission', 'status': 'PERMISSION_DENIED'}
ERROR:telegram.ext.Application:No error handlers are registered, logging exception.
Traceback (most recent call last):
  File "/home/KamilSultan/.local/lib/python3.13/site-packages/telegram/ext/_application.py", line 1124, in process_update
    await coroutine
  File "/home/KamilSultan/.local/lib/python3.13/site-packages/telegram/ext/_conversationhandler.py", line 825, in handle_update
    new_state: object = await handler.handle_update(
                        ^^^^^^^^^^^^^^^^^^^^^^^^^^^^
        update, application, handler_check_result, context
        ^^^^^^^^^^^^^^^^^^^^^^^^^^^^^^^^^^^^^^^^^^^^^^^^^^
    )
    ^
  File "/home/KamilSultan/.local/lib/python3.13/site-packages/telegram/ext/_handler.py", line 141, in handle_update
    return await self.callback(update, context)
           ^^^^^^^^^^^^^^^^^^^^^^^^^^^^^^^^^^^^
  File "/home/KamilSultan/psych_bot/bot.py", line 69, in get_message1
    write_message(row, user_id, message, is_first=True)
    ~~~~~~~~~~~~~^^^^^^^^^^^^^^^^^^^^^^^^^^^^^^^^^^^^^^
  File "/home/KamilSultan/psych_bot/sheets.py", line 48, in write_message
    sheet.update_cell(row, col_uid, str(user_id))
    ~~~~~~~~~~~~~~~~~^^^^^^^^^^^^^^^^^^^^^^^^^^^^
  File "/home/KamilSultan/.local/lib/python3.13/site-packages/gspread/worksheet.py", line 857, in update_cell
    data = self.spreadsheet.values_update(
        range_name,
        params={"valueInputOption": ValueInputOption.user_entered},
        body={"values": [[value]]},
    )
  File "/home/KamilSultan/.local/lib/python3.13/site-packages/gspread/spreadsheet.py", line 219, in values_update
    r = self.client.request("put", url, params=params, json=body)
  File "/home/KamilSultan/.local/lib/python3.13/site-packages/gspread/client.py", line 93, in request
    raise APIError(response)
gspread.exceptions.APIError: {'code': 403, 'message': 'The caller does not have permission', 'status': 'PERMISSION_DENIED'}
ERROR:root:[GoogleSheets] Ошибка записи сообщения: {'code': 403, 'message': 'The caller does not have permission', 'status': 'PERMISSION_DENIED'}
ERROR:telegram.ext.Application:No error handlers are registered, logging exception.
Traceback (most recent call last):
  File "/home/KamilSultan/.local/lib/python3.13/site-packages/telegram/ext/_application.py", line 1124, in process_update
    await coroutine
  File "/home/KamilSultan/.local/lib/python3.13/site-packages/telegram/ext/_conversationhandler.py", line 825, in handle_update
    new_state: object = await handler.handle_update(
                        ^^^^^^^^^^^^^^^^^^^^^^^^^^^^
        update, application, handler_check_result, context
        ^^^^^^^^^^^^^^^^^^^^^^^^^^^^^^^^^^^^^^^^^^^^^^^^^^
    )
    ^
  File "/home/KamilSultan/.local/lib/python3.13/site-packages/telegram/ext/_handler.py", line 141, in handle_update
    return await self.callback(update, context)
           ^^^^^^^^^^^^^^^^^^^^^^^^^^^^^^^^^^^^
  File "/home/KamilSultan/psych_bot/bot.py", line 63, in get_message1
    write_message(row, user_id, message, is_first=True)
    ~~~~~~~~~~~~~^^^^^^^^^^^^^^^^^^^^^^^^^^^^^^^^^^^^^^
  File "/home/KamilSultan/psych_bot/sheets.py", line 48, in write_message
    sheet.update_cell(row, col_uid, str(user_id))
    ~~~~~~~~~~~~~~~~~^^^^^^^^^^^^^^^^^^^^^^^^^^^^
  File "/home/KamilSultan/.local/lib/python3.13/site-packages/gspread/worksheet.py", line 857, in update_cell
    data = self.spreadsheet.values_update(
        range_name,
        params={"valueInputOption": ValueInputOption.user_entered},
        body={"values": [[value]]},
    )
  File "/home/KamilSultan/.local/lib/python3.13/site-packages/gspread/spreadsheet.py", line 219, in values_update
    r = self.client.request("put", url, params=params, json=body)
  File "/home/KamilSultan/.local/lib/python3.13/site-packages/gspread/client.py", line 93, in request
    raise APIError(response)
gspread.exceptions.APIError: {'code': 403, 'message': 'The caller does not have permission', 'status': 'PERMISSION_DENIED'}
ERROR:root:[GoogleSheets] Ошибка записи сообщения: {'code': 403, 'message': 'The caller does not have permission', 'status': 'PERMISSION_DENIED'}
ERROR:telegram.ext.Application:No error handlers are registered, logging exception.
Traceback (most recent call last):
  File "/home/KamilSultan/.local/lib/python3.13/site-packages/telegram/ext/_application.py", line 1124, in process_update
    await coroutine
  File "/home/KamilSultan/.local/lib/python3.13/site-packages/telegram/ext/_conversationhandler.py", line 825, in handle_update
    new_state: object = await handler.handle_update(
                        ^^^^^^^^^^^^^^^^^^^^^^^^^^^^
        update, application, handler_check_result, context
        ^^^^^^^^^^^^^^^^^^^^^^^^^^^^^^^^^^^^^^^^^^^^^^^^^^
    )
    ^
  File "/home/KamilSultan/.local/lib/python3.13/site-packages/telegram/ext/_handler.py", line 141, in handle_update
    return await self.callback(update, context)
           ^^^^^^^^^^^^^^^^^^^^^^^^^^^^^^^^^^^^
  File "/home/KamilSultan/psych_bot/bot.py", line 63, in get_message1
    write_message(row, user_id, message, is_first=True)
    ~~~~~~~~~~~~~^^^^^^^^^^^^^^^^^^^^^^^^^^^^^^^^^^^^^^
  File "/home/KamilSultan/psych_bot/sheets.py", line 48, in write_message
    sheet.update_cell(row, col_uid, str(user_id))
    ~~~~~~~~~~~~~~~~~^^^^^^^^^^^^^^^^^^^^^^^^^^^^
  File "/home/KamilSultan/.local/lib/python3.13/site-packages/gspread/worksheet.py", line 857, in update_cell
    data = self.spreadsheet.values_update(
        range_name,
        params={"valueInputOption": ValueInputOption.user_entered},
        body={"values": [[value]]},
    )
  File "/home/KamilSultan/.local/lib/python3.13/site-packages/gspread/spreadsheet.py", line 219, in values_update
    r = self.client.request("put", url, params=params, json=body)
  File "/home/KamilSultan/.local/lib/python3.13/site-packages/gspread/client.py", line 93, in request
    raise APIError(response)
gspread.exceptions.APIError: {'code': 403, 'message': 'The caller does not have permission', 'status': 'PERMISSION_DENIED'}
ERROR:root:[GoogleSheets] Ошибка записи сообщения: {'code': 403, 'message': 'The caller does not have permission', 'status': 'PERMISSION_DENIED'}
ERROR:telegram.ext.Application:No error handlers are registered, logging exception.
Traceback (most recent call last):
  File "/home/KamilSultan/.local/lib/python3.13/site-packages/telegram/ext/_application.py", line 1124, in process_update
    await coroutine
  File "/home/KamilSultan/.local/lib/python3.13/site-packages/telegram/ext/_conversationhandler.py", line 825, in handle_update
    new_state: object = await handler.handle_update(
                        ^^^^^^^^^^^^^^^^^^^^^^^^^^^^
        update, application, handler_check_result, context
        ^^^^^^^^^^^^^^^^^^^^^^^^^^^^^^^^^^^^^^^^^^^^^^^^^^
    )
    ^
  File "/home/KamilSultan/.local/lib/python3.13/site-packages/telegram/ext/_handler.py", line 141, in handle_update
    return await self.callback(update, context)
           ^^^^^^^^^^^^^^^^^^^^^^^^^^^^^^^^^^^^
  File "/home/KamilSultan/psych_bot/bot.py", line 63, in get_message1
    write_message(row, user_id, message, is_first=True)
    ~~~~~~~~~~~~~^^^^^^^^^^^^^^^^^^^^^^^^^^^^^^^^^^^^^^
  File "/home/KamilSultan/psych_bot/sheets.py", line 48, in write_message
    sheet.update_cell(row, col_uid, str(user_id))
    ~~~~~~~~~~~~~~~~~^^^^^^^^^^^^^^^^^^^^^^^^^^^^
  File "/home/KamilSultan/.local/lib/python3.13/site-packages/gspread/worksheet.py", line 857, in update_cell
    data = self.spreadsheet.values_update(
        range_name,
        params={"valueInputOption": ValueInputOption.user_entered},
        body={"values": [[value]]},
    )
  File "/home/KamilSultan/.local/lib/python3.13/site-packages/gspread/spreadsheet.py", line 219, in values_update
    r = self.client.request("put", url, params=params, json=body)
  File "/home/KamilSultan/.local/lib/python3.13/site-packages/gspread/client.py", line 93, in request
    raise APIError(response)
gspread.exceptions.APIError: {'code': 403, 'message': 'The caller does not have permission', 'status': 'PERMISSION_DENIED'}
ERROR:root:[GoogleSheets] Ошибка записи сообщения: {'code': 403, 'message': 'The caller does not have permission', 'status': 'PERMISSION_DENIED'}
ERROR:telegram.ext.Application:No error handlers are registered, logging exception.
Traceback (most recent call last):
  File "/home/KamilSultan/.local/lib/python3.13/site-packages/telegram/ext/_application.py", line 1124, in process_update
    await coroutine
  File "/home/KamilSultan/.local/lib/python3.13/site-packages/telegram/ext/_conversationhandler.py", line 825, in handle_update
    new_state: object = await handler.handle_update(
                        ^^^^^^^^^^^^^^^^^^^^^^^^^^^^
        update, application, handler_check_result, context
        ^^^^^^^^^^^^^^^^^^^^^^^^^^^^^^^^^^^^^^^^^^^^^^^^^^
    )
    ^
  File "/home/KamilSultan/.local/lib/python3.13/site-packages/telegram/ext/_handler.py", line 141, in handle_update
    return await self.callback(update, context)
           ^^^^^^^^^^^^^^^^^^^^^^^^^^^^^^^^^^^^
  File "/home/KamilSultan/psych_bot/bot.py", line 63, in get_message1
    write_message(row, user_id, message, is_first=True)
    ~~~~~~~~~~~~~^^^^^^^^^^^^^^^^^^^^^^^^^^^^^^^^^^^^^^
  File "/home/KamilSultan/psych_bot/sheets.py", line 48, in write_message
    sheet.update_cell(row, col_uid, str(user_id))
    ~~~~~~~~~~~~~~~~~^^^^^^^^^^^^^^^^^^^^^^^^^^^^
  File "/home/KamilSultan/.local/lib/python3.13/site-packages/gspread/worksheet.py", line 857, in update_cell
    data = self.spreadsheet.values_update(
        range_name,
        params={"valueInputOption": ValueInputOption.user_entered},
        body={"values": [[value]]},
    )
  File "/home/KamilSultan/.local/lib/python3.13/site-packages/gspread/spreadsheet.py", line 219, in values_update
    r = self.client.request("put", url, params=params, json=body)
  File "/home/KamilSultan/.local/lib/python3.13/site-packages/gspread/client.py", line 93, in request
    raise APIError(response)
gspread.exceptions.APIError: {'code': 403, 'message': 'The caller does not have permission', 'status': 'PERMISSION_DENIED'}
ERROR:root:[GoogleSheets] Ошибка записи сообщения: {'code': 403, 'message': 'The caller does not have permission', 'status': 'PERMISSION_DENIED'}
ERROR:telegram.ext.Application:No error handlers are registered, logging exception.
Traceback (most recent call last):
  File "/home/KamilSultan/.local/lib/python3.13/site-packages/telegram/ext/_application.py", line 1124, in process_update
    await coroutine
  File "/home/KamilSultan/.local/lib/python3.13/site-packages/telegram/ext/_conversationhandler.py", line 825, in handle_update
    new_state: object = await handler.handle_update(
                        ^^^^^^^^^^^^^^^^^^^^^^^^^^^^
        update, application, handler_check_result, context
        ^^^^^^^^^^^^^^^^^^^^^^^^^^^^^^^^^^^^^^^^^^^^^^^^^^
    )
    ^
  File "/home/KamilSultan/.local/lib/python3.13/site-packages/telegram/ext/_handler.py", line 141, in handle_update
    return await self.callback(update, context)
           ^^^^^^^^^^^^^^^^^^^^^^^^^^^^^^^^^^^^
  File "/home/KamilSultan/psych_bot/bot.py", line 63, in get_message1
    write_message(row, user_id, message, is_first=True)
    ~~~~~~~~~~~~~^^^^^^^^^^^^^^^^^^^^^^^^^^^^^^^^^^^^^^
  File "/home/KamilSultan/psych_bot/sheets.py", line 48, in write_message
    sheet.update_cell(row, col_uid, str(user_id))
    ~~~~~~~~~~~~~~~~~^^^^^^^^^^^^^^^^^^^^^^^^^^^^
  File "/home/KamilSultan/.local/lib/python3.13/site-packages/gspread/worksheet.py", line 857, in update_cell
    data = self.spreadsheet.values_update(
        range_name,
        params={"valueInputOption": ValueInputOption.user_entered},
        body={"values": [[value]]},
    )
  File "/home/KamilSultan/.local/lib/python3.13/site-packages/gspread/spreadsheet.py", line 219, in values_update
    r = self.client.request("put", url, params=params, json=body)
  File "/home/KamilSultan/.local/lib/python3.13/site-packages/gspread/client.py", line 93, in request
    raise APIError(response)
gspread.exceptions.APIError: {'code': 403, 'message': 'The caller does not have permission', 'status': 'PERMISSION_DENIED'}
ERROR:root:[GoogleSheets] Ошибка записи сообщения: {'code': 403, 'message': 'The caller does not have permission', 'status': 'PERMISSION_DENIED'}
ERROR:telegram.ext.Application:No error handlers are registered, logging exception.
Traceback (most recent call last):
  File "/home/KamilSultan/.local/lib/python3.13/site-packages/telegram/ext/_application.py", line 1124, in process_update
    await coroutine
  File "/home/KamilSultan/.local/lib/python3.13/site-packages/telegram/ext/_conversationhandler.py", line 825, in handle_update
    new_state: object = await handler.handle_update(
                        ^^^^^^^^^^^^^^^^^^^^^^^^^^^^
        update, application, handler_check_result, context
        ^^^^^^^^^^^^^^^^^^^^^^^^^^^^^^^^^^^^^^^^^^^^^^^^^^
    )
    ^
  File "/home/KamilSultan/.local/lib/python3.13/site-packages/telegram/ext/_handler.py", line 141, in handle_update
    return await self.callback(update, context)
           ^^^^^^^^^^^^^^^^^^^^^^^^^^^^^^^^^^^^
  File "/home/KamilSultan/psych_bot/bot.py", line 63, in get_message1
    write_message(row, user_id, message, is_first=True)
    ~~~~~~~~~~~~~^^^^^^^^^^^^^^^^^^^^^^^^^^^^^^^^^^^^^^
  File "/home/KamilSultan/psych_bot/sheets.py", line 48, in write_message
    sheet.update_cell(row, col_uid, str(user_id))
    ~~~~~~~~~~~~~~~~~^^^^^^^^^^^^^^^^^^^^^^^^^^^^
  File "/home/KamilSultan/.local/lib/python3.13/site-packages/gspread/worksheet.py", line 857, in update_cell
    data = self.spreadsheet.values_update(
        range_name,
        params={"valueInputOption": ValueInputOption.user_entered},
        body={"values": [[value]]},
    )
  File "/home/KamilSultan/.local/lib/python3.13/site-packages/gspread/spreadsheet.py", line 219, in values_update
    r = self.client.request("put", url, params=params, json=body)
  File "/home/KamilSultan/.local/lib/python3.13/site-packages/gspread/client.py", line 93, in request
    raise APIError(response)
gspread.exceptions.APIError: {'code': 403, 'message': 'The caller does not have permission', 'status': 'PERMISSION_DENIED'}
ERROR:root:[GoogleSheets] Ошибка записи сообщения: {'code': 403, 'message': 'The caller does not have permission', 'status': 'PERMISSION_DENIED'}
ERROR:telegram.ext.Application:No error handlers are registered, logging exception.
Traceback (most recent call last):
  File "/home/KamilSultan/.local/lib/python3.13/site-packages/telegram/ext/_application.py", line 1124, in process_update
    await coroutine
  File "/home/KamilSultan/.local/lib/python3.13/site-packages/telegram/ext/_conversationhandler.py", line 825, in handle_update
    new_state: object = await handler.handle_update(
                        ^^^^^^^^^^^^^^^^^^^^^^^^^^^^
        update, application, handler_check_result, context
        ^^^^^^^^^^^^^^^^^^^^^^^^^^^^^^^^^^^^^^^^^^^^^^^^^^
    )
    ^
  File "/home/KamilSultan/.local/lib/python3.13/site-packages/telegram/ext/_handler.py", line 141, in handle_update
    return await self.callback(update, context)
           ^^^^^^^^^^^^^^^^^^^^^^^^^^^^^^^^^^^^
  File "/home/KamilSultan/psych_bot/bot.py", line 63, in get_message1
    write_message(row, user_id, message, is_first=True)
    ~~~~~~~~~~~~~^^^^^^^^^^^^^^^^^^^^^^^^^^^^^^^^^^^^^^
  File "/home/KamilSultan/psych_bot/sheets.py", line 48, in write_message
    sheet.update_cell(row, col_uid, str(user_id))
    ~~~~~~~~~~~~~~~~~^^^^^^^^^^^^^^^^^^^^^^^^^^^^
  File "/home/KamilSultan/.local/lib/python3.13/site-packages/gspread/worksheet.py", line 857, in update_cell
    data = self.spreadsheet.values_update(
        range_name,
        params={"valueInputOption": ValueInputOption.user_entered},
        body={"values": [[value]]},
    )
  File "/home/KamilSultan/.local/lib/python3.13/site-packages/gspread/spreadsheet.py", line 219, in values_update
    r = self.client.request("put", url, params=params, json=body)
  File "/home/KamilSultan/.local/lib/python3.13/site-packages/gspread/client.py", line 93, in request
    raise APIError(response)
gspread.exceptions.APIError: {'code': 403, 'message': 'The caller does not have permission', 'status': 'PERMISSION_DENIED'}
ERROR:telegram.ext.Application:No error handlers are registered, logging exception.
Traceback (most recent call last):
  File "/home/KamilSultan/.local/lib/python3.13/site-packages/telegram/ext/_application.py", line 1124, in process_update
    await coroutine
  File "/home/KamilSultan/.local/lib/python3.13/site-packages/telegram/ext/_conversationhandler.py", line 825, in handle_update
    new_state: object = await handler.handle_update(
                        ^^^^^^^^^^^^^^^^^^^^^^^^^^^^
        update, application, handler_check_result, context
        ^^^^^^^^^^^^^^^^^^^^^^^^^^^^^^^^^^^^^^^^^^^^^^^^^^
    )
    ^
  File "/home/KamilSultan/.local/lib/python3.13/site-packages/telegram/ext/_handler.py", line 141, in handle_update
    return await self.callback(update, context)
           ^^^^^^^^^^^^^^^^^^^^^^^^^^^^^^^^^^^^
  File "/home/KamilSultan/psych_bot/bot.py", line 61, in get_message1
    return reset()
TypeError: reset() missing 2 required positional arguments: 'update' and 'context'
ERROR:telegram.ext.Application:No error handlers are registered, logging exception.
Traceback (most recent call last):
  File "/home/KamilSultan/.local/lib/python3.13/site-packages/telegram/ext/_application.py", line 1124, in process_update
    await coroutine
  File "/home/KamilSultan/.local/lib/python3.13/site-packages/telegram/ext/_conversationhandler.py", line 825, in handle_update
    new_state: object = await handler.handle_update(
                        ^^^^^^^^^^^^^^^^^^^^^^^^^^^^
        update, application, handler_check_result, context
        ^^^^^^^^^^^^^^^^^^^^^^^^^^^^^^^^^^^^^^^^^^^^^^^^^^
    )
    ^
  File "/home/KamilSultan/.local/lib/python3.13/site-packages/telegram/ext/_handler.py", line 141, in handle_update
    return await self.callback(update, context)
           ^^^^^^^^^^^^^^^^^^^^^^^^^^^^^^^^^^^^
  File "/home/KamilSultan/psych_bot/bot.py", line 61, in get_message1
    return reset()
TypeError: reset() missing 2 required positional arguments: 'update' and 'context'
ERROR:telegram.ext.Application:No error handlers are registered, logging exception.
Traceback (most recent call last):
  File "/home/KamilSultan/.local/lib/python3.13/site-packages/telegram/ext/_application.py", line 1124, in process_update
    await coroutine
  File "/home/KamilSultan/.local/lib/python3.13/site-packages/telegram/ext/_conversationhandler.py", line 825, in handle_update
    new_state: object = await handler.handle_update(
                        ^^^^^^^^^^^^^^^^^^^^^^^^^^^^
        update, application, handler_check_result, context
        ^^^^^^^^^^^^^^^^^^^^^^^^^^^^^^^^^^^^^^^^^^^^^^^^^^
    )
    ^
  File "/home/KamilSultan/.local/lib/python3.13/site-packages/telegram/ext/_handler.py", line 141, in handle_update
    return await self.callback(update, context)
           ^^^^^^^^^^^^^^^^^^^^^^^^^^^^^^^^^^^^
  File "/home/KamilSultan/psych_bot/bot.py", line 61, in get_message1
    return await reset(update, context)
           ^^^^^^^
TypeError: reset() missing 2 required positional arguments: 'update' and 'context'
ERROR:telegram.ext.Application:No error handlers are registered, logging exception.
Traceback (most recent call last):
  File "/home/KamilSultan/.local/lib/python3.13/site-packages/telegram/ext/_application.py", line 1124, in process_update
    await coroutine
  File "/home/KamilSultan/.local/lib/python3.13/site-packages/telegram/ext/_conversationhandler.py", line 825, in handle_update
    new_state: object = await handler.handle_update(
                        ^^^^^^^^^^^^^^^^^^^^^^^^^^^^
        update, application, handler_check_result, context
        ^^^^^^^^^^^^^^^^^^^^^^^^^^^^^^^^^^^^^^^^^^^^^^^^^^
    )
    ^
  File "/home/KamilSultan/.local/lib/python3.13/site-packages/telegram/ext/_handler.py", line 141, in handle_update
    return await self.callback(update, context)
           ^^^^^^^^^^^^^^^^^^^^^^^^^^^^^^^^^^^^
  File "/home/KamilSultan/psych_bot/bot.py", line 55, in choose_device
    return await reset(update, context)
           ^^^^^^^^^^^^^^^^^^^^^^^^^^^^
  File "/home/KamilSultan/psych_bot/bot.py", line 109, in reset
    if message == reset_action:
       ^^^^^^^
NameError: name 'message' is not defined
ERROR:telegram.ext.Application:No error handlers are registered, logging exception.
Traceback (most recent call last):
  File "/home/KamilSultan/.local/lib/python3.13/site-packages/telegram/ext/_application.py", line 1124, in process_update
    await coroutine
  File "/home/KamilSultan/.local/lib/python3.13/site-packages/telegram/ext/_conversationhandler.py", line 825, in handle_update
    new_state: object = await handler.handle_update(
                        ^^^^^^^^^^^^^^^^^^^^^^^^^^^^
        update, application, handler_check_result, context
        ^^^^^^^^^^^^^^^^^^^^^^^^^^^^^^^^^^^^^^^^^^^^^^^^^^
    )
    ^
  File "/home/KamilSultan/.local/lib/python3.13/site-packages/telegram/ext/_handler.py", line 141, in handle_update
    return await self.callback(update, context)
           ^^^^^^^^^^^^^^^^^^^^^^^^^^^^^^^^^^^^
  File "/home/KamilSultan/psych_bot/bot.py", line 72, in get_message1
    return await resetAction(update, context)
           ^^^^^^^^^^^^^^^^^^^^^^^^^^^^
  File "/home/KamilSultan/psych_bot/bot.py", line 109, in reset
    user_id = update.message.from_user.id
       ^^^^^^^
NameError: name 'message' is not defined
ERROR:telegram.ext.Application:No error handlers are registered, logging exception.
Traceback (most recent call last):
  File "/home/KamilSultan/.local/lib/python3.13/site-packages/telegram/ext/_application.py", line 1124, in process_update
    await coroutine
  File "/home/KamilSultan/.local/lib/python3.13/site-packages/telegram/ext/_conversationhandler.py", line 825, in handle_update
    new_state: object = await handler.handle_update(
                        ^^^^^^^^^^^^^^^^^^^^^^^^^^^^
        update, application, handler_check_result, context
        ^^^^^^^^^^^^^^^^^^^^^^^^^^^^^^^^^^^^^^^^^^^^^^^^^^
    )
    ^
  File "/home/KamilSultan/.local/lib/python3.13/site-packages/telegram/ext/_handler.py", line 141, in handle_update
    return await self.callback(update, context)
           ^^^^^^^^^^^^^^^^^^^^^^^^^^^^^^^^^^^^
  File "/home/KamilSultan/psych_bot/bot.py", line 72, in get_message1
    return await resetAction(update, context)
           ^^^^^^^^^^^^^^^^^^^^^^^^^^^^
  File "/home/KamilSultan/psych_bot/bot.py", line 109, in reset
    user_id = update.message.from_user.id
       ^^^^^^^
NameError: name 'message' is not defined
ERROR:telegram.ext.Application:No error handlers are registered, logging exception.
Traceback (most recent call last):
  File "/home/KamilSultan/.local/lib/python3.13/site-packages/telegram/ext/_application.py", line 1124, in process_update
    await coroutine
  File "/home/KamilSultan/.local/lib/python3.13/site-packages/telegram/ext/_conversationhandler.py", line 825, in handle_update
    new_state: object = await handler.handle_update(
                        ^^^^^^^^^^^^^^^^^^^^^^^^^^^^
        update, application, handler_check_result, context
        ^^^^^^^^^^^^^^^^^^^^^^^^^^^^^^^^^^^^^^^^^^^^^^^^^^
    )
    ^
  File "/home/KamilSultan/.local/lib/python3.13/site-packages/telegram/ext/_handler.py", line 141, in handle_update
    return await self.callback(update, context)
           ^^^^^^^^^^^^^^^^^^^^^^^^^^^^^^^^^^^^
  File "/home/KamilSultan/psych_bot/bot.py", line 72, in get_message1
    return await resetAction(update, context)
           ^^^^^^^^^^^^^^^^^^^^^^^^^^^^
  File "/home/KamilSultan/psych_bot/bot.py", line 109, in reset
    user_id = update.message.from_user.id
       ^^^^^^^
NameError: name 'message' is not defined
ERROR:telegram.ext.Application:No error handlers are registered, logging exception.
Traceback (most recent call last):
  File "/home/KamilSultan/.local/lib/python3.13/site-packages/telegram/ext/_application.py", line 1124, in process_update
    await coroutine
  File "/home/KamilSultan/.local/lib/python3.13/site-packages/telegram/ext/_conversationhandler.py", line 825, in handle_update
    new_state: object = await handler.handle_update(
                        ^^^^^^^^^^^^^^^^^^^^^^^^^^^^
        update, application, handler_check_result, context
        ^^^^^^^^^^^^^^^^^^^^^^^^^^^^^^^^^^^^^^^^^^^^^^^^^^
    )
    ^
  File "/home/KamilSultan/.local/lib/python3.13/site-packages/telegram/ext/_handler.py", line 141, in handle_update
    return await self.callback(update, context)
           ^^^^^^^^^^^^^^^^^^^^^^^^^^^^^^^^^^^^
  File "/home/KamilSultan/psych_bot/bot.py", line 72, in get_message1
    return await resetAction(update, context)
           ^^^^^^^^^^^^^^^^^^^^^^^^^^^^
  File "/home/KamilSultan/psych_bot/bot.py", line 109, in reset
    user_id = update.message.from_user.id
       ^^^^^^^
NameError: name 'message' is not defined
ERROR:telegram.ext.Application:No error handlers are registered, logging exception.
Traceback (most recent call last):
  File "/home/KamilSultan/.local/lib/python3.13/site-packages/telegram/ext/_application.py", line 1124, in process_update
    await coroutine
  File "/home/KamilSultan/.local/lib/python3.13/site-packages/telegram/ext/_conversationhandler.py", line 825, in handle_update
    new_state: object = await handler.handle_update(
                        ^^^^^^^^^^^^^^^^^^^^^^^^^^^^
        update, application, handler_check_result, context
        ^^^^^^^^^^^^^^^^^^^^^^^^^^^^^^^^^^^^^^^^^^^^^^^^^^
    )
    ^
  File "/home/KamilSultan/.local/lib/python3.13/site-packages/telegram/ext/_handler.py", line 141, in handle_update
    return await self.callback(update, context)
           ^^^^^^^^^^^^^^^^^^^^^^^^^^^^^^^^^^^^
  File "/home/KamilSultan/psych_bot/bot.py", line 72, in get_message1
    return await resetAction(update, context)
           ^^^^^^^^^^^^^^^^^^^^^^^^^^^^
  File "/home/KamilSultan/psych_bot/bot.py", line 109, in reset
    user_id = update.message.from_user.id
       ^^^^^^^
NameError: name 'message' is not defined
ERROR:telegram.ext.Application:No error handlers are registered, logging exception.
Traceback (most recent call last):
  File "/home/KamilSultan/.local/lib/python3.13/site-packages/telegram/ext/_application.py", line 1124, in process_update
    await coroutine
  File "/home/KamilSultan/.local/lib/python3.13/site-packages/telegram/ext/_conversationhandler.py", line 825, in handle_update
    new_state: object = await handler.handle_update(
                        ^^^^^^^^^^^^^^^^^^^^^^^^^^^^
        update, application, handler_check_result, context
        ^^^^^^^^^^^^^^^^^^^^^^^^^^^^^^^^^^^^^^^^^^^^^^^^^^
    )
    ^
  File "/home/KamilSultan/.local/lib/python3.13/site-packages/telegram/ext/_handler.py", line 141, in handle_update
    return await self.callback(update, context)
           ^^^^^^^^^^^^^^^^^^^^^^^^^^^^^^^^^^^^
  File "/home/KamilSultan/psych_bot/bot.py", line 72, in get_message1
    return await resetAction(update, context)
           ^^^^^^^^^^^^^^^^^^^^^^^^^^^^
  File "/home/KamilSultan/psych_bot/bot.py", line 109, in reset
    user_id = update.message.from_user.id
       ^^^^^^^
NameError: name 'message' is not defined
ERROR:telegram.ext.Application:No error handlers are registered, logging exception.
Traceback (most recent call last):
  File "/home/KamilSultan/.local/lib/python3.13/site-packages/telegram/ext/_application.py", line 1124, in process_update
    await coroutine
  File "/home/KamilSultan/.local/lib/python3.13/site-packages/telegram/ext/_conversationhandler.py", line 825, in handle_update
    new_state: object = await handler.handle_update(
                        ^^^^^^^^^^^^^^^^^^^^^^^^^^^^
        update, application, handler_check_result, context
        ^^^^^^^^^^^^^^^^^^^^^^^^^^^^^^^^^^^^^^^^^^^^^^^^^^
    )
    ^
  File "/home/KamilSultan/.local/lib/python3.13/site-packages/telegram/ext/_handler.py", line 141, in handle_update
    return await self.callback(update, context)
           ^^^^^^^^^^^^^^^^^^^^^^^^^^^^^^^^^^^^
  File "/home/KamilSultan/psych_bot/bot.py", line 70, in get_message1
    uid_1, msgid_1 = read_messages(row)
    ^^^^^^^^^^^^^^
ValueError: too many values to unpack (expected 2)
ERROR:telegram.ext.Application:No error handlers are registered, logging exception.
Traceback (most recent call last):
  File "/home/KamilSultan/.local/lib/python3.13/site-packages/telegram/ext/_application.py", line 1124, in process_update
    await coroutine
  File "/home/KamilSultan/.local/lib/python3.13/site-packages/telegram/ext/_conversationhandler.py", line 825, in handle_update
    new_state: object = await handler.handle_update(
                        ^^^^^^^^^^^^^^^^^^^^^^^^^^^^
        update, application, handler_check_result, context
        ^^^^^^^^^^^^^^^^^^^^^^^^^^^^^^^^^^^^^^^^^^^^^^^^^^
    )
    ^
  File "/home/KamilSultan/.local/lib/python3.13/site-packages/telegram/ext/_handler.py", line 141, in handle_update
    return await self.callback(update, context)
           ^^^^^^^^^^^^^^^^^^^^^^^^^^^^^^^^^^^^
  File "/home/KamilSultan/psych_bot/bot.py", line 70, in get_message1
    uid_1, msg_1 = read_messages(row)
    ^^^^^^^^^^^^
ValueError: too many values to unpack (expected 2)
ERROR:telegram.ext.Application:No error handlers are registered, logging exception.
Traceback (most recent call last):
  File "/home/KamilSultan/.local/lib/python3.13/site-packages/telegram/ext/_application.py", line 1124, in process_update
    await coroutine
  File "/home/KamilSultan/.local/lib/python3.13/site-packages/telegram/ext/_conversationhandler.py", line 825, in handle_update
    new_state: object = await handler.handle_update(
                        ^^^^^^^^^^^^^^^^^^^^^^^^^^^^
        update, application, handler_check_result, context
        ^^^^^^^^^^^^^^^^^^^^^^^^^^^^^^^^^^^^^^^^^^^^^^^^^^
    )
    ^
  File "/home/KamilSultan/.local/lib/python3.13/site-packages/telegram/ext/_handler.py", line 141, in handle_update
    return await self.callback(update, context)
           ^^^^^^^^^^^^^^^^^^^^^^^^^^^^^^^^^^^^
  File "/home/KamilSultan/psych_bot/bot.py", line 70, in get_message1
    uid_1, msg_1 = read_messages(row)
    ^^^^^^^^^^^^
ValueError: too many values to unpack (expected 2)
ERROR:telegram.ext.Application:No error handlers are registered, logging exception.
Traceback (most recent call last):
  File "/home/KamilSultan/.local/lib/python3.13/site-packages/telegram/ext/_application.py", line 1124, in process_update
    await coroutine
  File "/home/KamilSultan/.local/lib/python3.13/site-packages/telegram/ext/_conversationhandler.py", line 825, in handle_update
    new_state: object = await handler.handle_update(
                        ^^^^^^^^^^^^^^^^^^^^^^^^^^^^
        update, application, handler_check_result, context
        ^^^^^^^^^^^^^^^^^^^^^^^^^^^^^^^^^^^^^^^^^^^^^^^^^^
    )
    ^
  File "/home/KamilSultan/.local/lib/python3.13/site-packages/telegram/ext/_handler.py", line 141, in handle_update
    return await self.callback(update, context)
           ^^^^^^^^^^^^^^^^^^^^^^^^^^^^^^^^^^^^
  File "/home/KamilSultan/psych_bot/bot.py", line 70, in get_message1
    uid_1, msg_1 = read_messages(row)
    ^^^^^^^^^^^^
ValueError: too many values to unpack (expected 2)
ERROR:telegram.ext.Application:No error handlers are registered, logging exception.
Traceback (most recent call last):
  File "/home/KamilSultan/.local/lib/python3.13/site-packages/telegram/ext/_application.py", line 1124, in process_update
    await coroutine
  File "/home/KamilSultan/.local/lib/python3.13/site-packages/telegram/ext/_conversationhandler.py", line 825, in handle_update
    new_state: object = await handler.handle_update(
                        ^^^^^^^^^^^^^^^^^^^^^^^^^^^^
        update, application, handler_check_result, context
        ^^^^^^^^^^^^^^^^^^^^^^^^^^^^^^^^^^^^^^^^^^^^^^^^^^
    )
    ^
  File "/home/KamilSultan/.local/lib/python3.13/site-packages/telegram/ext/_handler.py", line 141, in handle_update
    return await self.callback(update, context)
           ^^^^^^^^^^^^^^^^^^^^^^^^^^^^^^^^^^^^
  File "/home/KamilSultan/psych_bot/bot.py", line 58, in choose_device
    uid_1, msg_1, uid_2, msg_2 = read_messages(row)
                                               ^^^
NameError: name 'row' is not defined. Did you mean: 'pow'?
ERROR:telegram.ext.Application:No error handlers are registered, logging exception.
Traceback (most recent call last):
  File "/home/KamilSultan/.local/lib/python3.13/site-packages/telegram/ext/_application.py", line 1124, in process_update
    await coroutine
  File "/home/KamilSultan/.local/lib/python3.13/site-packages/telegram/ext/_conversationhandler.py", line 825, in handle_update
    new_state: object = await handler.handle_update(
                        ^^^^^^^^^^^^^^^^^^^^^^^^^^^^
        update, application, handler_check_result, context
        ^^^^^^^^^^^^^^^^^^^^^^^^^^^^^^^^^^^^^^^^^^^^^^^^^^
    )
    ^
  File "/home/KamilSultan/.local/lib/python3.13/site-packages/telegram/ext/_handler.py", line 141, in handle_update
    return await self.callback(update, context)
           ^^^^^^^^^^^^^^^^^^^^^^^^^^^^^^^^^^^^
  File "/home/KamilSultan/psych_bot/bot.py", line 58, in choose_device
    uid_1, msg_1, uid_2, msg_2 = read_messages(row)
                                               ^^^
NameError: name 'row' is not defined. Did you mean: 'pow'?
ERROR:root:[GPT] Ошибка с моделью openai/gpt-4o: Код: 402 | {"error":{"message":"This request requires more credits, or fewer max_tokens. You requested up to 1000 tokens, but can only afford 960. To increase, visit https://openrouter.ai/settings/credits and upgrade to a paid account","code":402,"metadata":{"provider_name":null}},"user_id":"user_2yEbVfDzUm3gZaKSeuRlPbqvTju"}
ERROR:root:[GPT] Ошибка с моделью openai/gpt-3.5-turbo: Код: 404 | {"error":{"message":"No endpoints found for openai/gpt-3.5-turbo.","code":404},"user_id":"user_2yEbVfDzUm3gZaKSeuRlPbqvTju"}
ERROR:root:[GPT] Ошибка с моделью deepseek-ai/deepseek-coder: Код: 400 | {"error":{"message":"deepseek-ai/deepseek-coder is not a valid model ID","code":400},"user_id":"user_2yEbVfDzUm3gZaKSeuRlPbqvTju"}
ERROR:root:[GPT] Ошибка с моделью google/gemini-pro: Код: 400 | {"error":{"message":"google/gemini-pro is not a valid model ID","code":400},"user_id":"user_2yEbVfDzUm3gZaKSeuRlPbqvTju"}
ERROR:root:[GPT] Ошибка с моделью openai/gpt-4o: Код: 402 | {"error":{"message":"This request requires more credits, or fewer max_tokens. You requested up to 1000 tokens, but can only afford 959. To increase, visit https://openrouter.ai/settings/credits and upgrade to a paid account","code":402,"metadata":{"provider_name":null}},"user_id":"user_2yEbVfDzUm3gZaKSeuRlPbqvTju"}
ERROR:root:[GPT] Ошибка с моделью openai/gpt-3.5-turbo: Код: 404 | {"error":{"message":"No endpoints found for openai/gpt-3.5-turbo.","code":404},"user_id":"user_2yEbVfDzUm3gZaKSeuRlPbqvTju"}
ERROR:root:[GPT] Ошибка с моделью deepseek-ai/deepseek-coder: Код: 400 | {"error":{"message":"deepseek-ai/deepseek-coder is not a valid model ID","code":400},"user_id":"user_2yEbVfDzUm3gZaKSeuRlPbqvTju"}
ERROR:root:[GPT] Ошибка с моделью google/gemini-pro: Код: 400 | {"error":{"message":"google/gemini-pro is not a valid model ID","code":400},"user_id":"user_2yEbVfDzUm3gZaKSeuRlPbqvTju"}
ERROR:root:[GPT] Ошибка с моделью openai/gpt-4o: Код: 402 | {"error":{"message":"This request requires more credits, or fewer max_tokens. You requested up to 1000 tokens, but can only afford 958. To increase, visit https://openrouter.ai/settings/credits and upgrade to a paid account","code":402,"metadata":{"provider_name":null}},"user_id":"user_2yEbVfDzUm3gZaKSeuRlPbqvTju"}
ERROR:root:[GPT] Ошибка с моделью openai/gpt-3.5-turbo: Код: 404 | {"error":{"message":"No endpoints found for openai/gpt-3.5-turbo.","code":404},"user_id":"user_2yEbVfDzUm3gZaKSeuRlPbqvTju"}
ERROR:root:[GPT] Ошибка с моделью deepseek-ai/deepseek-coder: Код: 400 | {"error":{"message":"deepseek-ai/deepseek-coder is not a valid model ID","code":400},"user_id":"user_2yEbVfDzUm3gZaKSeuRlPbqvTju"}
ERROR:root:[GPT] Ошибка с моделью google/gemini-pro: Код: 400 | {"error":{"message":"google/gemini-pro is not a valid model ID","code":400},"user_id":"user_2yEbVfDzUm3gZaKSeuRlPbqvTju"}
ERROR:root:[GPT] Ошибка с моделью openai/gpt-4o: Код: 402 | {"error":{"message":"This request requires more credits, or fewer max_tokens. You requested up to 1000 tokens, but can only afford 957. To increase, visit https://openrouter.ai/settings/credits and upgrade to a paid account","code":402,"metadata":{"provider_name":null}},"user_id":"user_2yEbVfDzUm3gZaKSeuRlPbqvTju"}
ERROR:root:[GPT] Ошибка с моделью openai/gpt-3.5-turbo: Код: 404 | {"error":{"message":"No endpoints found for openai/gpt-3.5-turbo.","code":404},"user_id":"user_2yEbVfDzUm3gZaKSeuRlPbqvTju"}
ERROR:root:[GPT] Ошибка с моделью deepseek-ai/deepseek-coder: Код: 400 | {"error":{"message":"deepseek-ai/deepseek-coder is not a valid model ID","code":400},"user_id":"user_2yEbVfDzUm3gZaKSeuRlPbqvTju"}
ERROR:root:[GPT] Ошибка с моделью google/gemini-pro: Код: 400 | {"error":{"message":"google/gemini-pro is not a valid model ID","code":400},"user_id":"user_2yEbVfDzUm3gZaKSeuRlPbqvTju"}
ERROR:root:[BOT] Ошибка анализа: name 'uid_1' is not defined
ERROR:root:[GPT] Ошибка с моделью openai/gpt-4o: Код: 402 | {"error":{"message":"This request requires more credits, or fewer max_tokens. You requested up to 1000 tokens, but can only afford 956. To increase, visit https://openrouter.ai/settings/credits and upgrade to a paid account","code":402,"metadata":{"provider_name":null}},"user_id":"user_2yEbVfDzUm3gZaKSeuRlPbqvTju"}
ERROR:root:[GPT] Ошибка с моделью openai/gpt-3.5-turbo: Код: 404 | {"error":{"message":"No endpoints found for openai/gpt-3.5-turbo.","code":404},"user_id":"user_2yEbVfDzUm3gZaKSeuRlPbqvTju"}
ERROR:root:[GPT] Ошибка с моделью deepseek-ai/deepseek-coder: Код: 400 | {"error":{"message":"deepseek-ai/deepseek-coder is not a valid model ID","code":400},"user_id":"user_2yEbVfDzUm3gZaKSeuRlPbqvTju"}
ERROR:root:[GPT] Ошибка с моделью google/gemini-pro: Код: 400 | {"error":{"message":"google/gemini-pro is not a valid model ID","code":400},"user_id":"user_2yEbVfDzUm3gZaKSeuRlPbqvTju"}
ERROR:root:[GPT] Ошибка с моделью openai/gpt-4o: Код: 402 | {"error":{"message":"This request requires more credits, or fewer max_tokens. You requested up to 1000 tokens, but can only afford 955. To increase, visit https://openrouter.ai/settings/credits and upgrade to a paid account","code":402,"metadata":{"provider_name":null}},"user_id":"user_2yEbVfDzUm3gZaKSeuRlPbqvTju"}
ERROR:root:[GPT] Ошибка с моделью openai/gpt-3.5-turbo: Код: 404 | {"error":{"message":"No endpoints found for openai/gpt-3.5-turbo.","code":404},"user_id":"user_2yEbVfDzUm3gZaKSeuRlPbqvTju"}
ERROR:root:[GPT] Ошибка с моделью deepseek-ai/deepseek-coder: Код: 400 | {"error":{"message":"deepseek-ai/deepseek-coder is not a valid model ID","code":400},"user_id":"user_2yEbVfDzUm3gZaKSeuRlPbqvTju"}
ERROR:root:[GPT] Ошибка с моделью google/gemini-pro: Код: 400 | {"error":{"message":"google/gemini-pro is not a valid model ID","code":400},"user_id":"user_2yEbVfDzUm3gZaKSeuRlPbqvTju"}
ERROR:root:[GPT] Ошибка с моделью openai/gpt-4o: Код: 402 | {"error":{"message":"This request requires more credits, or fewer max_tokens. You requested up to 1000 tokens, but can only afford 955. To increase, visit https://openrouter.ai/settings/credits and upgrade to a paid account","code":402,"metadata":{"provider_name":null}},"user_id":"user_2yEbVfDzUm3gZaKSeuRlPbqvTju"}
ERROR:root:[GPT] Ошибка с моделью openai/gpt-3.5-turbo: Код: 404 | {"error":{"message":"No endpoints found for openai/gpt-3.5-turbo.","code":404},"user_id":"user_2yEbVfDzUm3gZaKSeuRlPbqvTju"}
ERROR:root:[GPT] Ошибка с моделью deepseek-ai/deepseek-coder: Код: 400 | {"error":{"message":"deepseek-ai/deepseek-coder is not a valid model ID","code":400},"user_id":"user_2yEbVfDzUm3gZaKSeuRlPbqvTju"}
ERROR:root:[GPT] Ошибка с моделью google/gemini-pro: Код: 400 | {"error":{"message":"google/gemini-pro is not a valid model ID","code":400},"user_id":"user_2yEbVfDzUm3gZaKSeuRlPbqvTju"}
ERROR:telegram.ext.Application:No error handlers are registered, logging exception.
Traceback (most recent call last):
  File "/home/KamilSultan/.local/lib/python3.13/site-packages/telegram/ext/_application.py", line 1124, in process_update
    await coroutine
  File "/home/KamilSultan/.local/lib/python3.13/site-packages/telegram/ext/_conversationhandler.py", line 825, in handle_update
    new_state: object = await handler.handle_update(
                        ^^^^^^^^^^^^^^^^^^^^^^^^^^^^
        update, application, handler_check_result, context
        ^^^^^^^^^^^^^^^^^^^^^^^^^^^^^^^^^^^^^^^^^^^^^^^^^^
    )
    ^
  File "/home/KamilSultan/.local/lib/python3.13/site-packages/telegram/ext/_handler.py", line 141, in handle_update
    return await self.callback(update, context)
           ^^^^^^^^^^^^^^^^^^^^^^^^^^^^^^^^^^^^
  File "/home/KamilSultan/psych_bot/bot.py", line 31, in get_code
    row = find_row_by_code(code)
  File "/home/KamilSultan/psych_bot/sheets.py", line 29, in find_row_by_code
    codes = sheet.col_values(CODE)
  File "/home/KamilSultan/.local/lib/python3.13/site-packages/gspread/worksheet.py", line 814, in col_values
    start_label = rowcol_to_a1(1, col)
  File "/home/KamilSultan/.local/lib/python3.13/site-packages/gspread/utils.py", line 285, in rowcol_to_a1
    raise IncorrectCellLabel("({}, {})".format(row, col))
gspread.exceptions.IncorrectCellLabel: (1, 0)
ERROR:root:[GPT] Ошибка с моделью openai/gpt-4o: Код: 402 | {"error":{"message":"This request requires more credits, or fewer max_tokens. You requested up to 1000 tokens, but can only afford 954. To increase, visit https://openrouter.ai/settings/credits and upgrade to a paid account","code":402,"metadata":{"provider_name":null}},"user_id":"user_2yEbVfDzUm3gZaKSeuRlPbqvTju"}
ERROR:root:[GPT] Ошибка с моделью openai/gpt-3.5-turbo: Код: 404 | {"error":{"message":"No endpoints found for openai/gpt-3.5-turbo.","code":404},"user_id":"user_2yEbVfDzUm3gZaKSeuRlPbqvTju"}
ERROR:root:[GPT] Ошибка с моделью deepseek-ai/deepseek-coder: Код: 400 | {"error":{"message":"deepseek-ai/deepseek-coder is not a valid model ID","code":400},"user_id":"user_2yEbVfDzUm3gZaKSeuRlPbqvTju"}
ERROR:root:[GPT] Ошибка с моделью google/gemini-pro: Код: 400 | {"error":{"message":"google/gemini-pro is not a valid model ID","code":400},"user_id":"user_2yEbVfDzUm3gZaKSeuRlPbqvTju"}
ERROR:telegram.ext.Application:No error handlers are registered, logging exception.
Traceback (most recent call last):
  File "/home/KamilSultan/.local/lib/python3.13/site-packages/telegram/ext/_application.py", line 1124, in process_update
    await coroutine
  File "/home/KamilSultan/.local/lib/python3.13/site-packages/telegram/ext/_conversationhandler.py", line 825, in handle_update
    new_state: object = await handler.handle_update(
                        ^^^^^^^^^^^^^^^^^^^^^^^^^^^^
        update, application, handler_check_result, context
        ^^^^^^^^^^^^^^^^^^^^^^^^^^^^^^^^^^^^^^^^^^^^^^^^^^
    )
    ^
  File "/home/KamilSultan/.local/lib/python3.13/site-packages/telegram/ext/_handler.py", line 141, in handle_update
    return await self.callback(update, context)
           ^^^^^^^^^^^^^^^^^^^^^^^^^^^^^^^^^^^^
  File "/home/KamilSultan/psych_bot/bot.py", line 48, in question_answer_start
    await update.message.reply_text(questions[0].question, reply_markup=reply_markup2)
                                    ^^^^^^^^^^^^^^^^^^^^^
AttributeError: 'dict' object has no attribute 'question'
ERROR:telegram.ext.Application:No error handlers are registered, logging exception.
Traceback (most recent call last):
  File "/home/KamilSultan/.local/lib/python3.13/site-packages/telegram/ext/_application.py", line 1124, in process_update
    await coroutine
  File "/home/KamilSultan/.local/lib/python3.13/site-packages/telegram/ext/_conversationhandler.py", line 825, in handle_update
    new_state: object = await handler.handle_update(
                        ^^^^^^^^^^^^^^^^^^^^^^^^^^^^
        update, application, handler_check_result, context
        ^^^^^^^^^^^^^^^^^^^^^^^^^^^^^^^^^^^^^^^^^^^^^^^^^^
    )
    ^
  File "/home/KamilSultan/.local/lib/python3.13/site-packages/telegram/ext/_handler.py", line 141, in handle_update
    return await self.callback(update, context)
           ^^^^^^^^^^^^^^^^^^^^^^^^^^^^^^^^^^^^
  File "/home/KamilSultan/psych_bot/bot.py", line 48, in question_answer_start
    await update.message.reply_text(questions[0].question, reply_markup=reply_markup2)
                                    ^^^^^^^^^^^^^^^^^^^^^
AttributeError: 'dict' object has no attribute 'question'
ERROR:telegram.ext.Application:No error handlers are registered, logging exception.
Traceback (most recent call last):
  File "/home/KamilSultan/.local/lib/python3.13/site-packages/telegram/ext/_application.py", line 1124, in process_update
    await coroutine
  File "/home/KamilSultan/.local/lib/python3.13/site-packages/telegram/ext/_conversationhandler.py", line 825, in handle_update
    new_state: object = await handler.handle_update(
                        ^^^^^^^^^^^^^^^^^^^^^^^^^^^^
        update, application, handler_check_result, context
        ^^^^^^^^^^^^^^^^^^^^^^^^^^^^^^^^^^^^^^^^^^^^^^^^^^
    )
    ^
  File "/home/KamilSultan/.local/lib/python3.13/site-packages/telegram/ext/_handler.py", line 141, in handle_update
    return await self.callback(update, context)
           ^^^^^^^^^^^^^^^^^^^^^^^^^^^^^^^^^^^^
  File "/home/KamilSultan/psych_bot/bot.py", line 48, in question_answer_start
    await update.message.reply_text(questions[0].question, reply_markup=reply_markup2)
                                    ^^^^^^^^^^^^^^^^^^^^^
AttributeError: 'dict' object has no attribute 'question'
ERROR:telegram.ext.Application:No error handlers are registered, logging exception.
Traceback (most recent call last):
  File "/home/KamilSultan/.local/lib/python3.13/site-packages/telegram/ext/_application.py", line 1124, in process_update
    await coroutine
  File "/home/KamilSultan/.local/lib/python3.13/site-packages/telegram/ext/_conversationhandler.py", line 825, in handle_update
    new_state: object = await handler.handle_update(
                        ^^^^^^^^^^^^^^^^^^^^^^^^^^^^
        update, application, handler_check_result, context
        ^^^^^^^^^^^^^^^^^^^^^^^^^^^^^^^^^^^^^^^^^^^^^^^^^^
    )
    ^
  File "/home/KamilSultan/.local/lib/python3.13/site-packages/telegram/ext/_handler.py", line 141, in handle_update
    return await self.callback(update, context)
           ^^^^^^^^^^^^^^^^^^^^^^^^^^^^^^^^^^^^
  File "/home/KamilSultan/psych_bot/bot.py", line 48, in question_answer_start
    await update.message.reply_text(questions[0].question, reply_markup=reply_markup2)
                                    ^^^^^^^^^^^^^^^^^^^^^
AttributeError: 'dict' object has no attribute 'question'
